Workbook

Sheet 【１】キーワード
B1: キーワード | D1: 済月 | E1: 46043 | F1: 過去キーワード一覧
A2: 1 | B2: figma Lancer Altria Pendragon DX Edition Fate Grand Order Max Factory Japan Neu | D2: 4月 | E2: 46278 | F2: ポケモンジム ヤマブキシティ
A3: 2 | D3: 5月 | F3: ANA フライングホヌ
A4: 3 | D4: 6月 | F4: 大久保篤画集
A5: 4 | D5: 7月 | F5: 星のカービィ ぬいぐるみ
A6: 5 | D6: 8月 | F6: セガサターン ストリートファイター
A7: 6 | D7: 3月 | F7: ハリーポッター レプリカ 教科書
A8: 7 | D8: 2月 | F8: THE BLUE HEARTS レコード
A9: 8 | F9: スタートレック コレクション ボーグキューブ
A10: 9 | F10: スキャンティ ニーソックス
A11: 10 | F11: ケナー ロストワールド レックス | I11: 46181
A12: 11 | F12: デジモンテイマーズ くたキャラ ギルモン ぬいぐるみ
A13: 12 | F13: 暁月のフィナーレ コレクターズ（アルミボトルも）
A14: 13 | F14: ミュウツーの逆襲 ピカチュウ プロも
A15: 14 | F15: ワンピース ハイパーバトル ルフィの帽子
A16: 15 | F16: リンチェイス ジャガージャングル プレート
A17: 16 | F17: トイストーリー ラウンドアップ絵皿
A18: 17 | F18: HUNTER×HUNTER グリードアイランド パーフェクトコレクタブル
A19: 18 | F19: IsatPhone Pro
A20: 19 | F20: U.S.S. NCC-1701-D | I20: 46189
A21: 20 | F21: 小澤征爾 グラモフォン録音全集
F22: デビルっちのたまごっち ピンク
F23: ラビュリンス デュエルセット
F24: SHODO SUPER 五星戦隊ダイレンジャー
F25: Ultimate Breaks Complete Collection CD
F26: Williams FW14 SENNA
F27: 三日月閑 フィギュア
F28: ねんどろいど デスストランディング クリフ DX
F29: ヴァリエイブルヒーローズ ナミ
F30: 刀装具 町彫 名品聚成 | I30: 46199
F31: 大久保篤画集 SOUL EATER SOUL ART
F32: バナナフィッシュ サウンドトラック レコード
F33: ねんどろいど ラルセイ
F34: ワンピース カードダス C07 ゾロ
F35: ノワール 寝起きフィギュア
F36: 精神壊しの罠 foil
F37: DAVID BOWIE FIVE YEARS 1969-1973 CD
F38: スーパーファミコン HAGANE
F39: Charlotte プレミアムフィギュア 友利奈緒
F40: QWER Beyond the Discord | I40: 46146
...

Sheet 【２】結果
A1: 数式 | B1: ● | C1: ● | D1: ● 各種数字→ | E1: 1 | F1: 2 | G1: 3 | H1: 4 | I1: 5 | J1: 6 | K1: 7 | L1: 8 | M1: 9 | N1: 10 | O1: 11 | P1: 12 | Q1: 13 | R1: 14 | S1: 15 | T1: 16 | U1: 17 | V1: 18 | W1: 19 | X1: 20
A2: 商品番号 | B2: 全コピー | C2: 件数 | D2: タイトル | E2: 1語目-1 | F2: 1語目-2 | G2: 1語目-3 | H2: 1語目-4 | I2: 1語目-5 | J2: 2語目-1 | K2: 2語目-2 | L2: 2語目-3 | M2: 2語目-4 | N2: 2語目-5 | O2: 3語目-1 | P2: 3語目-2 | Q2: 3語目-3 | R2: 3語目-4 | S2: 3語目-5 | T2: 4語目-1 | U2: 4語目-2 | V2: 4語目-3 | W2: 4語目-4 | X2: 4語目-5 | Z2: キーワード1
A3: 1 | B3: =MID(IF(E3="","",CHAR(10)&E3)&IF(F3="","",CHAR(10)&F3)&IF(G3="","",CHAR(10)&G3)&IF(H3="","",CHAR(10)&H3)&IF(I3="","",CHAR(10)&I3)&IF(J3="","",CHAR(10)&J3)&IF(K3="","",CHAR(10)&K3)&IF(L3="","",CHAR(10)&L3)&IF(M3="","",CHAR(10)&M3)&IF(N3="","",CHAR(10)&N3)&IF(O3="","",CHAR(10)&O3)&IF(P3="","",CHAR(10)&P3)&IF(Q3="","",CHAR(10)&Q3)&IF(R3="","",CHAR(10)&R3)&IF(S3="","",CHAR(10)&S3)&IF(T3="","",CHAR(10)&T3)&IF(U3="","",CHAR(10)&U3)&IF(V3="","",CHAR(10)&V3)&IF(W3="","",CHAR(10)&W3)&IF(X3="","",CHAR(10)&X3),2,30000) | C3: =COUNTIF(E3:X3,"http*") -> 0 | D3: =IF(【１】キーワード!B2="","",【１】キーワード!B2) -> figma Lancer Altria Pendragon DX Edition Fate Grand Order Max Factory Japan Neu | Z3: 1語目
A4: 2 | B4: =MID(IF(E4="","",CHAR(10)&E4)&IF(F4="","",CHAR(10)&F4)&IF(G4="","",CHAR(10)&G4)&IF(H4="","",CHAR(10)&H4)&IF(I4="","",CHAR(10)&I4)&IF(J4="","",CHAR(10)&J4)&IF(K4="","",CHAR(10)&K4)&IF(L4="","",CHAR(10)&L4)&IF(M4="","",CHAR(10)&M4)&IF(N4="","",CHAR(10)&N4)&IF(O4="","",CHAR(10)&O4)&IF(P4="","",CHAR(10)&P4)&IF(Q4="","",CHAR(10)&Q4)&IF(R4="","",CHAR(10)&R4)&IF(S4="","",CHAR(10)&S4)&IF(T4="","",CHAR(10)&T4)&IF(U4="","",CHAR(10)&U4)&IF(V4="","",CHAR(10)&V4)&IF(W4="","",CHAR(10)&W4)&IF(X4="","",CHAR(10)&X4),2,30000) | C4: =COUNTIF(E4:X4,"http*") -> 0 | D4: =IF(【１】キーワード!B3="","",【１】キーワード!B3) | Z4: 2語目
A5: 3 | B5: =MID(IF(E5="","",CHAR(10)&E5)&IF(F5="","",CHAR(10)&F5)&IF(G5="","",CHAR(10)&G5)&IF(H5="","",CHAR(10)&H5)&IF(I5="","",CHAR(10)&I5)&IF(J5="","",CHAR(10)&J5)&IF(K5="","",CHAR(10)&K5)&IF(L5="","",CHAR(10)&L5)&IF(M5="","",CHAR(10)&M5)&IF(N5="","",CHAR(10)&N5)&IF(O5="","",CHAR(10)&O5)&IF(P5="","",CHAR(10)&P5)&IF(Q5="","",CHAR(10)&Q5)&IF(R5="","",CHAR(10)&R5)&IF(S5="","",CHAR(10)&S5)&IF(T5="","",CHAR(10)&T5)&IF(U5="","",CHAR(10)&U5)&IF(V5="","",CHAR(10)&V5)&IF(W5="","",CHAR(10)&W5)&IF(X5="","",CHAR(10)&X5),2,30000) | C5: =COUNTIF(E5:X5,"http*") -> 0 | D5: =IF(【１】キーワード!B4="","",【１】キーワード!B4) | Z5: 3語目
A6: 4 | B6: =MID(IF(E6="","",CHAR(10)&E6)&IF(F6="","",CHAR(10)&F6)&IF(G6="","",CHAR(10)&G6)&IF(H6="","",CHAR(10)&H6)&IF(I6="","",CHAR(10)&I6)&IF(J6="","",CHAR(10)&J6)&IF(K6="","",CHAR(10)&K6)&IF(L6="","",CHAR(10)&L6)&IF(M6="","",CHAR(10)&M6)&IF(N6="","",CHAR(10)&N6)&IF(O6="","",CHAR(10)&O6)&IF(P6="","",CHAR(10)&P6)&IF(Q6="","",CHAR(10)&Q6)&IF(R6="","",CHAR(10)&R6)&IF(S6="","",CHAR(10)&S6)&IF(T6="","",CHAR(10)&T6)&IF(U6="","",CHAR(10)&U6)&IF(V6="","",CHAR(10)&V6)&IF(W6="","",CHAR(10)&W6)&IF(X6="","",CHAR(10)&X6),2,30000) | C6: =COUNTIF(E6:X6,"http*") -> 0 | D6: =IF(【１】キーワード!B5="","",【１】キーワード!B5) | Z6: 4語目
A7: 5 | B7: =MID(IF(E7="","",CHAR(10)&E7)&IF(F7="","",CHAR(10)&F7)&IF(G7="","",CHAR(10)&G7)&IF(H7="","",CHAR(10)&H7)&IF(I7="","",CHAR(10)&I7)&IF(J7="","",CHAR(10)&J7)&IF(K7="","",CHAR(10)&K7)&IF(L7="","",CHAR(10)&L7)&IF(M7="","",CHAR(10)&M7)&IF(N7="","",CHAR(10)&N7)&IF(O7="","",CHAR(10)&O7)&IF(P7="","",CHAR(10)&P7)&IF(Q7="","",CHAR(10)&Q7)&IF(R7="","",CHAR(10)&R7)&IF(S7="","",CHAR(10)&S7)&IF(T7="","",CHAR(10)&T7)&IF(U7="","",CHAR(10)&U7)&IF(V7="","",CHAR(10)&V7)&IF(W7="","",CHAR(10)&W7)&IF(X7="","",CHAR(10)&X7),2,30000) | C7: =COUNTIF(E7:X7,"http*") -> 0 | D7: =IF(【１】キーワード!B6="","",【１】キーワード!B6)
A8: 6 | B8: =MID(IF(E8="","",CHAR(10)&E8)&IF(F8="","",CHAR(10)&F8)&IF(G8="","",CHAR(10)&G8)&IF(H8="","",CHAR(10)&H8)&IF(I8="","",CHAR(10)&I8)&IF(J8="","",CHAR(10)&J8)&IF(K8="","",CHAR(10)&K8)&IF(L8="","",CHAR(10)&L8)&IF(M8="","",CHAR(10)&M8)&IF(N8="","",CHAR(10)&N8)&IF(O8="","",CHAR(10)&O8)&IF(P8="","",CHAR(10)&P8)&IF(Q8="","",CHAR(10)&Q8)&IF(R8="","",CHAR(10)&R8)&IF(S8="","",CHAR(10)&S8)&IF(T8="","",CHAR(10)&T8)&IF(U8="","",CHAR(10)&U8)&IF(V8="","",CHAR(10)&V8)&IF(W8="","",CHAR(10)&W8)&IF(X8="","",CHAR(10)&X8),2,30000) | C8: =COUNTIF(E8:X8,"http*") -> 0 | D8: =IF(【１】キーワード!B7="","",【１】キーワード!B7) | Z8: キーワード2
A9: 7 | B9: =MID(IF(E9="","",CHAR(10)&E9)&IF(F9="","",CHAR(10)&F9)&IF(G9="","",CHAR(10)&G9)&IF(H9="","",CHAR(10)&H9)&IF(I9="","",CHAR(10)&I9)&IF(J9="","",CHAR(10)&J9)&IF(K9="","",CHAR(10)&K9)&IF(L9="","",CHAR(10)&L9)&IF(M9="","",CHAR(10)&M9)&IF(N9="","",CHAR(10)&N9)&IF(O9="","",CHAR(10)&O9)&IF(P9="","",CHAR(10)&P9)&IF(Q9="","",CHAR(10)&Q9)&IF(R9="","",CHAR(10)&R9)&IF(S9="","",CHAR(10)&S9)&IF(T9="","",CHAR(10)&T9)&IF(U9="","",CHAR(10)&U9)&IF(V9="","",CHAR(10)&V9)&IF(W9="","",CHAR(10)&W9)&IF(X9="","",CHAR(10)&X9),2,30000) | C9: =COUNTIF(E9:X9,"http*") -> 0 | D9: =IF(【１】キーワード!B8="","",【１】キーワード!B8) | Z9: 1語目
A10: 8 | B10: =MID(IF(E10="","",CHAR(10)&E10)&IF(F10="","",CHAR(10)&F10)&IF(G10="","",CHAR(10)&G10)&IF(H10="","",CHAR(10)&H10)&IF(I10="","",CHAR(10)&I10)&IF(J10="","",CHAR(10)&J10)&IF(K10="","",CHAR(10)&K10)&IF(L10="","",CHAR(10)&L10)&IF(M10="","",CHAR(10)&M10)&IF(N10="","",CHAR(10)&N10)&IF(O10="","",CHAR(10)&O10)&IF(P10="","",CHAR(10)&P10)&IF(Q10="","",CHAR(10)&Q10)&IF(R10="","",CHAR(10)&R10)&IF(S10="","",CHAR(10)&S10)&IF(T10="","",CHAR(10)&T10)&IF(U10="","",CHAR(10)&U10)&IF(V10="","",CHAR(10)&V10)&IF(W10="","",CHAR(10)&W10)&IF(X10="","",CHAR(10)&X10),2,30000) | C10: =COUNTIF(E10:X10,"http*") -> 0 | D10: =IF(【１】キーワード!B9="","",【１】キーワード!B9) | Z10: 2語目
A11: 9 | B11: =MID(IF(E11="","",CHAR(10)&E11)&IF(F11="","",CHAR(10)&F11)&IF(G11="","",CHAR(10)&G11)&IF(H11="","",CHAR(10)&H11)&IF(I11="","",CHAR(10)&I11)&IF(J11="","",CHAR(10)&J11)&IF(K11="","",CHAR(10)&K11)&IF(L11="","",CHAR(10)&L11)&IF(M11="","",CHAR(10)&M11)&IF(N11="","",CHAR(10)&N11)&IF(O11="","",CHAR(10)&O11)&IF(P11="","",CHAR(10)&P11)&IF(Q11="","",CHAR(10)&Q11)&IF(R11="","",CHAR(10)&R11)&IF(S11="","",CHAR(10)&S11)&IF(T11="","",CHAR(10)&T11)&IF(U11="","",CHAR(10)&U11)&IF(V11="","",CHAR(10)&V11)&IF(W11="","",CHAR(10)&W11)&IF(X11="","",CHAR(10)&X11),2,30000) | C11: =COUNTIF(E11:X11,"http*") -> 0 | D11: =IF(【１】キーワード!B10="","",【１】キーワード!B10) | Z11: 3語目
A12: 10 | B12: =MID(IF(E12="","",CHAR(10)&E12)&IF(F12="","",CHAR(10)&F12)&IF(G12="","",CHAR(10)&G12)&IF(H12="","",CHAR(10)&H12)&IF(I12="","",CHAR(10)&I12)&IF(J12="","",CHAR(10)&J12)&IF(K12="","",CHAR(10)&K12)&IF(L12="","",CHAR(10)&L12)&IF(M12="","",CHAR(10)&M12)&IF(N12="","",CHAR(10)&N12)&IF(O12="","",CHAR(10)&O12)&IF(P12="","",CHAR(10)&P12)&IF(Q12="","",CHAR(10)&Q12)&IF(R12="","",CHAR(10)&R12)&IF(S12="","",CHAR(10)&S12)&IF(T12="","",CHAR(10)&T12)&IF(U12="","",CHAR(10)&U12)&IF(V12="","",CHAR(10)&V12)&IF(W12="","",CHAR(10)&W12)&IF(X12="","",CHAR(10)&X12),2,30000) | C12: =COUNTIF(E12:X12,"http*") -> 0 | D12: =IF(【１】キーワード!B11="","",【１】キーワード!B11) | Z12: 4語目
A13: 11 | B13: =MID(IF(E13="","",CHAR(10)&E13)&IF(F13="","",CHAR(10)&F13)&IF(G13="","",CHAR(10)&G13)&IF(H13="","",CHAR(10)&H13)&IF(I13="","",CHAR(10)&I13)&IF(J13="","",CHAR(10)&J13)&IF(K13="","",CHAR(10)&K13)&IF(L13="","",CHAR(10)&L13)&IF(M13="","",CHAR(10)&M13)&IF(N13="","",CHAR(10)&N13)&IF(O13="","",CHAR(10)&O13)&IF(P13="","",CHAR(10)&P13)&IF(Q13="","",CHAR(10)&Q13)&IF(R13="","",CHAR(10)&R13)&IF(S13="","",CHAR(10)&S13)&IF(T13="","",CHAR(10)&T13)&IF(U13="","",CHAR(10)&U13)&IF(V13="","",CHAR(10)&V13)&IF(W13="","",CHAR(10)&W13)&IF(X13="","",CHAR(10)&X13),2,30000) | C13: =COUNTIF(E13:X13,"http*") -> 0 | D13: =IF(【１】キーワード!B12="","",【１】キーワード!B12)
A14: 12 | B14: =MID(IF(E14="","",CHAR(10)&E14)&IF(F14="","",CHAR(10)&F14)&IF(G14="","",CHAR(10)&G14)&IF(H14="","",CHAR(10)&H14)&IF(I14="","",CHAR(10)&I14)&IF(J14="","",CHAR(10)&J14)&IF(K14="","",CHAR(10)&K14)&IF(L14="","",CHAR(10)&L14)&IF(M14="","",CHAR(10)&M14)&IF(N14="","",CHAR(10)&N14)&IF(O14="","",CHAR(10)&O14)&IF(P14="","",CHAR(10)&P14)&IF(Q14="","",CHAR(10)&Q14)&IF(R14="","",CHAR(10)&R14)&IF(S14="","",CHAR(10)&S14)&IF(T14="","",CHAR(10)&T14)&IF(U14="","",CHAR(10)&U14)&IF(V14="","",CHAR(10)&V14)&IF(W14="","",CHAR(10)&W14)&IF(X14="","",CHAR(10)&X14),2,30000) | C14: =COUNTIF(E14:X14,"http*") -> 0 | D14: =IF(【１】キーワード!B13="","",【１】キーワード!B13) | Z14: キーワード3
A15: 13 | B15: =MID(IF(E15="","",CHAR(10)&E15)&IF(F15="","",CHAR(10)&F15)&IF(G15="","",CHAR(10)&G15)&IF(H15="","",CHAR(10)&H15)&IF(I15="","",CHAR(10)&I15)&IF(J15="","",CHAR(10)&J15)&IF(K15="","",CHAR(10)&K15)&IF(L15="","",CHAR(10)&L15)&IF(M15="","",CHAR(10)&M15)&IF(N15="","",CHAR(10)&N15)&IF(O15="","",CHAR(10)&O15)&IF(P15="","",CHAR(10)&P15)&IF(Q15="","",CHAR(10)&Q15)&IF(R15="","",CHAR(10)&R15)&IF(S15="","",CHAR(10)&S15)&IF(T15="","",CHAR(10)&T15)&IF(U15="","",CHAR(10)&U15)&IF(V15="","",CHAR(10)&V15)&IF(W15="","",CHAR(10)&W15)&IF(X15="","",CHAR(10)&X15),2,30000) | C15: =COUNTIF(E15:X15,"http*") -> 0 | D15: =IF(【１】キーワード!B14="","",【１】キーワード!B14) | Z15: 1語目
A16: 14 | B16: =MID(IF(E16="","",CHAR(10)&E16)&IF(F16="","",CHAR(10)&F16)&IF(G16="","",CHAR(10)&G16)&IF(H16="","",CHAR(10)&H16)&IF(I16="","",CHAR(10)&I16)&IF(J16="","",CHAR(10)&J16)&IF(K16="","",CHAR(10)&K16)&IF(L16="","",CHAR(10)&L16)&IF(M16="","",CHAR(10)&M16)&IF(N16="","",CHAR(10)&N16)&IF(O16="","",CHAR(10)&O16)&IF(P16="","",CHAR(10)&P16)&IF(Q16="","",CHAR(10)&Q16)&IF(R16="","",CHAR(10)&R16)&IF(S16="","",CHAR(10)&S16)&IF(T16="","",CHAR(10)&T16)&IF(U16="","",CHAR(10)&U16)&IF(V16="","",CHAR(10)&V16)&IF(W16="","",CHAR(10)&W16)&IF(X16="","",CHAR(10)&X16),2,30000) | C16: =COUNTIF(E16:X16,"http*") -> 0 | D16: =IF(【１】キーワード!B15="","",【１】キーワード!B15) | Z16: 2語目
A17: 15 | B17: =MID(IF(E17="","",CHAR(10)&E17)&IF(F17="","",CHAR(10)&F17)&IF(G17="","",CHAR(10)&G17)&IF(H17="","",CHAR(10)&H17)&IF(I17="","",CHAR(10)&I17)&IF(J17="","",CHAR(10)&J17)&IF(K17="","",CHAR(10)&K17)&IF(L17="","",CHAR(10)&L17)&IF(M17="","",CHAR(10)&M17)&IF(N17="","",CHAR(10)&N17)&IF(O17="","",CHAR(10)&O17)&IF(P17="","",CHAR(10)&P17)&IF(Q17="","",CHAR(10)&Q17)&IF(R17="","",CHAR(10)&R17)&IF(S17="","",CHAR(10)&S17)&IF(T17="","",CHAR(10)&T17)&IF(U17="","",CHAR(10)&U17)&IF(V17="","",CHAR(10)&V17)&IF(W17="","",CHAR(10)&W17)&IF(X17="","",CHAR(10)&X17),2,30000) | C17: =COUNTIF(E17:X17,"http*") -> 0 | D17: =IF(【１】キーワード!B16="","",【１】キーワード!B16) | Z17: 3語目
A18: 16 | B18: =MID(IF(E18="","",CHAR(10)&E18)&IF(F18="","",CHAR(10)&F18)&IF(G18="","",CHAR(10)&G18)&IF(H18="","",CHAR(10)&H18)&IF(I18="","",CHAR(10)&I18)&IF(J18="","",CHAR(10)&J18)&IF(K18="","",CHAR(10)&K18)&IF(L18="","",CHAR(10)&L18)&IF(M18="","",CHAR(10)&M18)&IF(N18="","",CHAR(10)&N18)&IF(O18="","",CHAR(10)&O18)&IF(P18="","",CHAR(10)&P18)&IF(Q18="","",CHAR(10)&Q18)&IF(R18="","",CHAR(10)&R18)&IF(S18="","",CHAR(10)&S18)&IF(T18="","",CHAR(10)&T18)&IF(U18="","",CHAR(10)&U18)&IF(V18="","",CHAR(10)&V18)&IF(W18="","",CHAR(10)&W18)&IF(X18="","",CHAR(10)&X18),2,30000) | C18: =COUNTIF(E18:X18,"http*") -> 0 | D18: =IF(【１】キーワード!B17="","",【１】キーワード!B17) | Z18: 4語目
A19: 17 | B19: =MID(IF(E19="","",CHAR(10)&E19)&IF(F19="","",CHAR(10)&F19)&IF(G19="","",CHAR(10)&G19)&IF(H19="","",CHAR(10)&H19)&IF(I19="","",CHAR(10)&I19)&IF(J19="","",CHAR(10)&J19)&IF(K19="","",CHAR(10)&K19)&IF(L19="","",CHAR(10)&L19)&IF(M19="","",CHAR(10)&M19)&IF(N19="","",CHAR(10)&N19)&IF(O19="","",CHAR(10)&O19)&IF(P19="","",CHAR(10)&P19)&IF(Q19="","",CHAR(10)&Q19)&IF(R19="","",CHAR(10)&R19)&IF(S19="","",CHAR(10)&S19)&IF(T19="","",CHAR(10)&T19)&IF(U19="","",CHAR(10)&U19)&IF(V19="","",CHAR(10)&V19)&IF(W19="","",CHAR(10)&W19)&IF(X19="","",CHAR(10)&X19),2,30000) | C19: =COUNTIF(E19:X19,"http*") -> 0 | D19: =IF(【１】キーワード!B18="","",【１】キーワード!B18)
A20: 18 | B20: =MID(IF(E20="","",CHAR(10)&E20)&IF(F20="","",CHAR(10)&F20)&IF(G20="","",CHAR(10)&G20)&IF(H20="","",CHAR(10)&H20)&IF(I20="","",CHAR(10)&I20)&IF(J20="","",CHAR(10)&J20)&IF(K20="","",CHAR(10)&K20)&IF(L20="","",CHAR(10)&L20)&IF(M20="","",CHAR(10)&M20)&IF(N20="","",CHAR(10)&N20)&IF(O20="","",CHAR(10)&O20)&IF(P20="","",CHAR(10)&P20)&IF(Q20="","",CHAR(10)&Q20)&IF(R20="","",CHAR(10)&R20)&IF(S20="","",CHAR(10)&S20)&IF(T20="","",CHAR(10)&T20)&IF(U20="","",CHAR(10)&U20)&IF(V20="","",CHAR(10)&V20)&IF(W20="","",CHAR(10)&W20)&IF(X20="","",CHAR(10)&X20),2,30000) | C20: =COUNTIF(E20:X20,"http*") -> 0 | D20: =IF(【１】キーワード!B19="","",【１】キーワード!B19) | Z20: キーワード4
A21: 19 | B21: =MID(IF(E21="","",CHAR(10)&E21)&IF(F21="","",CHAR(10)&F21)&IF(G21="","",CHAR(10)&G21)&IF(H21="","",CHAR(10)&H21)&IF(I21="","",CHAR(10)&I21)&IF(J21="","",CHAR(10)&J21)&IF(K21="","",CHAR(10)&K21)&IF(L21="","",CHAR(10)&L21)&IF(M21="","",CHAR(10)&M21)&IF(N21="","",CHAR(10)&N21)&IF(O21="","",CHAR(10)&O21)&IF(P21="","",CHAR(10)&P21)&IF(Q21="","",CHAR(10)&Q21)&IF(R21="","",CHAR(10)&R21)&IF(S21="","",CHAR(10)&S21)&IF(T21="","",CHAR(10)&T21)&IF(U21="","",CHAR(10)&U21)&IF(V21="","",CHAR(10)&V21)&IF(W21="","",CHAR(10)&W21)&IF(X21="","",CHAR(10)&X21),2,30000) | C21: =COUNTIF(E21:X21,"http*") -> 0 | D21: =IF(【１】キーワード!B20="","",【１】キーワード!B20) | Z21: 1語目
A22: 20 | B22: =MID(IF(E22="","",CHAR(10)&E22)&IF(F22="","",CHAR(10)&F22)&IF(G22="","",CHAR(10)&G22)&IF(H22="","",CHAR(10)&H22)&IF(I22="","",CHAR(10)&I22)&IF(J22="","",CHAR(10)&J22)&IF(K22="","",CHAR(10)&K22)&IF(L22="","",CHAR(10)&L22)&IF(M22="","",CHAR(10)&M22)&IF(N22="","",CHAR(10)&N22)&IF(O22="","",CHAR(10)&O22)&IF(P22="","",CHAR(10)&P22)&IF(Q22="","",CHAR(10)&Q22)&IF(R22="","",CHAR(10)&R22)&IF(S22="","",CHAR(10)&S22)&IF(T22="","",CHAR(10)&T22)&IF(U22="","",CHAR(10)&U22)&IF(V22="","",CHAR(10)&V22)&IF(W22="","",CHAR(10)&W22)&IF(X22="","",CHAR(10)&X22),2,30000) | C22: =COUNTIF(E22:X22,"http*") -> 0 | D22: =IF(【１】キーワード!B21="","",【１】キーワード!B21) | Z22: 2語目
Z23: 3語目
Z24: 4語目
Z26: キーワード5
Z27: 1語目
Z28: 2語目
Z29: 3語目
Z30: 4語目
Z32: キーワード6
Z33: 1語目
Z34: 2語目
Z35: 3語目
Z36: 4語目
... Z66: 4語目

Sheet 【３】出品リスト候補
B1: 仕入れ先候補 | C1: チェック | D1: 仕入れ先価格 | E1: 日本語タイトル | F1: 英語タイトル | G1: 抽出URL | H1: メルカリ | I1: ラクマ | J1: 楽天市場 | K1: ヤフオク | L1: ヤフーショッピング | M1: 結果 | N1: 予想 最安値($) | O1: 商品 重量(kg) | P1: 商品の 長さ(cm) | Q1: 商品の 幅(cm) | R1: 商品の 高さ(cm) | S1: 現在の米ドル円 為替($) | T1: 実重量 | U1: 容積重量 | V1: 大きい方 | W1: 繰り上げ | X1: 結果 | Y1: 予想送料 | Z1: 予想手数料 | AA1: 予想関税1 | AB1: 予想関税2 | AC1: 仕入値+ 送料+ 関税+ 手数料 | AD1: 予想最安値*為替 | AE1: 利益 （8500～9500円） | AG1: https://www.ebay.com/sch/i.html?_nkw=test&_sacat=0&_from=R40&_sop=15&rt=nc&_udlo=20000
A2: 1-1 | B2: =【２】結果!E3 -> 0 | T2: =O2 -> 0 | U2: =(P2*Q2*R2)/5000 -> 0 | V2: =MAX(T2,U2) -> 0 | W2: =CEILING(ROUNDDOWN(V2,2),0.5) -> 0 | X2: =VLOOKUP(W2,送料!$J$3:$K$42,2,FALSE) -> #N/A | Y2: =VLOOKUP(X2,送料!$A$1:$B$40,2,FALSE) -> #N/A | Z2: =(N2*S2)*0.16 -> 0 | AA2: =(N2*0.15)+4.5 -> 4.5 | AB2: =S2*AA2 -> 0 | AC2: =Y2+Z2+AB2+D2 -> #N/A | AD2: =N2*S2 -> 0 | AE2: =AD2-AC2 -> #N/A
A3: 1-2 | B3: =【２】結果!F3 -> 0 | T3: =O3 -> 0 | U3: =(P3*Q3*R3)/5000 -> 0 | V3: =MAX(T3,U3) -> 0 | W3: =CEILING(ROUNDDOWN(V3,2),0.5) -> 0 | X3: =VLOOKUP(W3,送料!$J$3:$K$42,2,FALSE) -> #N/A | Y3: =VLOOKUP(X3,送料!$A$1:$B$40,2,FALSE) -> #N/A | Z3: =(N3*S3)*0.16 -> 0 | AA3: =(N3*0.15)+4.5 -> 4.5 | AB3: =S3*AA3 -> 0 | AC3: =Y3+Z3+AB3+D3 -> #N/A | AD3: =N3*S3 -> 0 | AE3: =AD3-AC3 -> #N/A
A4: 1-3 | B4: =【２】結果!G3 -> 0 | T4: =O4 -> 0 | U4: =(P4*Q4*R4)/5000 -> 0 | V4: =MAX(T4,U4) -> 0 | W4: =CEILING(ROUNDDOWN(V4,2),0.5) -> 0 | X4: =VLOOKUP(W4,送料!$J$3:$K$42,2,FALSE) -> #N/A | Y4: =VLOOKUP(X4,送料!$A$1:$B$40,2,FALSE) -> #N/A | Z4: =(N4*S4)*0.16 -> 0 | AA4: =(N4*0.15)+4.5 -> 4.5 | AB4: =S4*AA4 -> 0 | AC4: =Y4+Z4+AB4+D4 -> #N/A | AD4: =N4*S4 -> 0 | AE4: =AD4-AC4 -> #N/A
A5: 1-4 | B5: =【２】結果!H3 -> 0 | T5: =O5 -> 0 | U5: =(P5*Q5*R5)/5000 -> 0 | V5: =MAX(T5,U5) -> 0 | W5: =CEILING(ROUNDDOWN(V5,2),0.5) -> 0 | X5: =VLOOKUP(W5,送料!$J$3:$K$42,2,FALSE) -> #N/A | Y5: =VLOOKUP(X5,送料!$A$1:$B$40,2,FALSE) -> #N/A | Z5: =(N5*S5)*0.16 -> 0 | AA5: =(N5*0.15)+4.5 -> 4.5 | AB5: =S5*AA5 -> 0 | AC5: =Y5+Z5+AB5+D5 -> #N/A | AD5: =N5*S5 -> 0 | AE5: =AD5-AC5 -> #N/A
A6: 1-5 | B6: =【２】結果!I3 -> 0 | T6: =O6 -> 0 | U6: =(P6*Q6*R6)/5000 -> 0 | V6: =MAX(T6,U6) -> 0 | W6: =CEILING(ROUNDDOWN(V6,2),0.5) -> 0 | X6: =VLOOKUP(W6,送料!$J$3:$K$42,2,FALSE) -> #N/A | Y6: =VLOOKUP(X6,送料!$A$1:$B$40,2,FALSE) -> #N/A | Z6: =(N6*S6)*0.16 -> 0 | AA6: =(N6*0.15)+4.5 -> 4.5 | AB6: =S6*AA6 -> 0 | AC6: =Y6+Z6+AB6+D6 -> #N/A | AD6: =N6*S6 -> 0 | AE6: =AD6-AC6 -> #N/A
A7: 1-6 | B7: =【２】結果!J3 -> 0 | T7: =O7 -> 0 | U7: =(P7*Q7*R7)/5000 -> 0 | V7: =MAX(T7,U7) -> 0 | W7: =CEILING(ROUNDDOWN(V7,2),0.5) -> 0 | X7: =VLOOKUP(W7,送料!$J$3:$K$42,2,FALSE) -> #N/A | Y7: =VLOOKUP(X7,送料!$A$1:$B$40,2,FALSE) -> #N/A | Z7: =(N7*S7)*0.16 -> 0 | AA7: =(N7*0.15)+4.5 -> 4.5 | AB7: =S7*AA7 -> 0 | AC7: =Y7+Z7+AB7+D7 -> #N/A | AD7: =N7*S7 -> 0 | AE7: =AD7-AC7 -> #N/A
A8: 1-7 | B8: =【２】結果!K3 -> 0 | T8: =O8 -> 0 | U8: =(P8*Q8*R8)/5000 -> 0 | V8: =MAX(T8,U8) -> 0 | W8: =CEILING(ROUNDDOWN(V8,2),0.5) -> 0 | X8: =VLOOKUP(W8,送料!$J$3:$K$42,2,FALSE) -> #N/A | Y8: =VLOOKUP(X8,送料!$A$1:$B$40,2,FALSE) -> #N/A | Z8: =(N8*S8)*0.16 -> 0 | AA8: =(N8*0.15)+4.5 -> 4.5 | AB8: =S8*AA8 -> 0 | AC8: =Y8+Z8+AB8+D8 -> #N/A | AD8: =N8*S8 -> 0 | AE8: =AD8-AC8 -> #N/A
A9: 1-8 | B9: =【２】結果!L3 -> 0 | T9: =O9 -> 0 | U9: =(P9*Q9*R9)/5000 -> 0 | V9: =MAX(T9,U9) -> 0 | W9: =CEILING(ROUNDDOWN(V9,2),0.5) -> 0 | X9: =VLOOKUP(W9,送料!$J$3:$K$42,2,FALSE) -> #N/A | Y9: =VLOOKUP(X9,送料!$A$1:$B$40,2,FALSE) -> #N/A | Z9: =(N9*S9)*0.16 -> 0 | AA9: =(N9*0.15)+4.5 -> 4.5 | AB9: =S9*AA9 -> 0 | AC9: =Y9+Z9+AB9+D9 -> #N/A | AD9: =N9*S9 -> 0 | AE9: =AD9-AC9 -> #N/A
A10: 1-9 | B10: =【２】結果!M3 -> 0 | T10: =O10 -> 0 | U10: =(P10*Q10*R10)/5000 -> 0 | V10: =MAX(T10,U10) -> 0 | W10: =CEILING(ROUNDDOWN(V10,2),0.5) -> 0 | X10: =VLOOKUP(W10,送料!$J$3:$K$42,2,FALSE) -> #N/A | Y10: =VLOOKUP(X10,送料!$A$1:$B$40,2,FALSE) -> #N/A | Z10: =(N10*S10)*0.16 -> 0 | AA10: =(N10*0.15)+4.5 -> 4.5 | AB10: =S10*AA10 -> 0 | AC10: =Y10+Z10+AB10+D10 -> #N/A | AD10: =N10*S10 -> 0 | AE10: =AD10-AC10 -> #N/A
A11: 1-10 | B11: =【２】結果!N3 -> 0 | T11: =O11 -> 0 | U11: =(P11*Q11*R11)/5000 -> 0 | V11: =MAX(T11,U11) -> 0 | W11: =CEILING(ROUNDDOWN(V11,2),0.5) -> 0 | X11: =VLOOKUP(W11,送料!$J$3:$K$42,2,FALSE) -> #N/A | Y11: =VLOOKUP(X11,送料!$A$1:$B$40,2,FALSE) -> #N/A | Z11: =(N11*S11)*0.16 -> 0 | AA11: =(N11*0.15)+4.5 -> 4.5 | AB11: =S11*AA11 -> 0 | AC11: =Y11+Z11+AB11+D11 -> #N/A | AD11: =N11*S11 -> 0 | AE11: =AD11-AC11 -> #N/A
A12: 1-11 | B12: =【２】結果!O3 -> 0 | T12: =O12 -> 0 | U12: =(P12*Q12*R12)/5000 -> 0 | V12: =MAX(T12,U12) -> 0 | W12: =CEILING(ROUNDDOWN(V12,2),0.5) -> 0 | X12: =VLOOKUP(W12,送料!$J$3:$K$42,2,FALSE) -> #N/A | Y12: =VLOOKUP(X12,送料!$A$1:$B$40,2,FALSE) -> #N/A | Z12: =(N12*S12)*0.16 -> 0 | AA12: =(N12*0.15)+4.5 -> 4.5 | AB12: =S12*AA12 -> 0 | AC12: =Y12+Z12+AB12+D12 -> #N/A | AD12: =N12*S12 -> 0 | AE12: =AD12-AC12 -> #N/A
A13: 1-12 | B13: =【２】結果!P3 -> 0 | T13: =O13 -> 0 | U13: =(P13*Q13*R13)/5000 -> 0 | V13: =MAX(T13,U13) -> 0 | W13: =CEILING(ROUNDDOWN(V13,2),0.5) -> 0 | X13: =VLOOKUP(W13,送料!$J$3:$K$42,2,FALSE) -> #N/A | Y13: =VLOOKUP(X13,送料!$A$1:$B$40,2,FALSE) -> #N/A | Z13: =(N13*S13)*0.16 -> 0 | AA13: =(N13*0.15)+4.5 -> 4.5 | AB13: =S13*AA13 -> 0 | AC13: =Y13+Z13+AB13+D13 -> #N/A | AD13: =N13*S13 -> 0 | AE13: =AD13-AC13 -> #N/A
A14: 1-13 | B14: =【２】結果!Q3 -> 0 | T14: =O14 -> 0 | U14: =(P14*Q14*R14)/5000 -> 0 | V14: =MAX(T14,U14) -> 0 | W14: =CEILING(ROUNDDOWN(V14,2),0.5) -> 0 | X14: =VLOOKUP(W14,送料!$J$3:$K$42,2,FALSE) -> #N/A | Y14: =VLOOKUP(X14,送料!$A$1:$B$40,2,FALSE) -> #N/A | Z14: =(N14*S14)*0.16 -> 0 | AA14: =(N14*0.15)+4.5 -> 4.5 | AB14: =S14*AA14 -> 0 | AC14: =Y14+Z14+AB14+D14 -> #N/A | AD14: =N14*S14 -> 0 | AE14: =AD14-AC14 -> #N/A
A15: 1-14 | B15: =【２】結果!R3 -> 0 | T15: =O15 -> 0 | U15: =(P15*Q15*R15)/5000 -> 0 | V15: =MAX(T15,U15) -> 0 | W15: =CEILING(ROUNDDOWN(V15,2),0.5) -> 0 | X15: =VLOOKUP(W15,送料!$J$3:$K$42,2,FALSE) -> #N/A | Y15: =VLOOKUP(X15,送料!$A$1:$B$40,2,FALSE) -> #N/A | Z15: =(N15*S15)*0.16 -> 0 | AA15: =(N15*0.15)+4.5 -> 4.5 | AB15: =S15*AA15 -> 0 | AC15: =Y15+Z15+AB15+D15 -> #N/A | AD15: =N15*S15 -> 0 | AE15: =AD15-AC15 -> #N/A
A16: 1-15 | B16: =【２】結果!S3 -> 0 | T16: =O16 -> 0 | U16: =(P16*Q16*R16)/5000 -> 0 | V16: =MAX(T16,U16) -> 0 | W16: =CEILING(ROUNDDOWN(V16,2),0.5) -> 0 | X16: =VLOOKUP(W16,送料!$J$3:$K$42,2,FALSE) -> #N/A | Y16: =VLOOKUP(X16,送料!$A$1:$B$40,2,FALSE) -> #N/A | Z16: =(N16*S16)*0.16 -> 0 | AA16: =(N16*0.15)+4.5 -> 4.5 | AB16: =S16*AA16 -> 0 | AC16: =Y16+Z16+AB16+D16 -> #N/A | AD16: =N16*S16 -> 0 | AE16: =AD16-AC16 -> #N/A
A17: 1-16 | B17: =【２】結果!T3 -> 0 | T17: =O17 -> 0 | U17: =(P17*Q17*R17)/5000 -> 0 | V17: =MAX(T17,U17) -> 0 | W17: =CEILING(ROUNDDOWN(V17,2),0.5) -> 0 | X17: =VLOOKUP(W17,送料!$J$3:$K$42,2,FALSE) -> #N/A | Y17: =VLOOKUP(X17,送料!$A$1:$B$40,2,FALSE) -> #N/A | Z17: =(N17*S17)*0.16 -> 0 | AA17: =(N17*0.15)+4.5 -> 4.5 | AB17: =S17*AA17 -> 0 | AC17: =Y17+Z17+AB17+D17 -> #N/A | AD17: =N17*S17 -> 0 | AE17: =AD17-AC17 -> #N/A
A18: 1-17 | B18: =【２】結果!U3 -> 0 | T18: =O18 -> 0 | U18: =(P18*Q18*R18)/5000 -> 0 | V18: =MAX(T18,U18) -> 0 | W18: =CEILING(ROUNDDOWN(V18,2),0.5) -> 0 | X18: =VLOOKUP(W18,送料!$J$3:$K$42,2,FALSE) -> #N/A | Y18: =VLOOKUP(X18,送料!$A$1:$B$40,2,FALSE) -> #N/A | Z18: =(N18*S18)*0.16 -> 0 | AA18: =(N18*0.15)+4.5 -> 4.5 | AB18: =S18*AA18 -> 0 | AC18: =Y18+Z18+AB18+D18 -> #N/A | AD18: =N18*S18 -> 0 | AE18: =AD18-AC18 -> #N/A
A19: 1-18 | B19: =【２】結果!V3 -> 0 | T19: =O19 -> 0 | U19: =(P19*Q19*R19)/5000 -> 0 | V19: =MAX(T19,U19) -> 0 | W19: =CEILING(ROUNDDOWN(V19,2),0.5) -> 0 | X19: =VLOOKUP(W19,送料!$J$3:$K$42,2,FALSE) -> #N/A | Y19: =VLOOKUP(X19,送料!$A$1:$B$40,2,FALSE) -> #N/A | Z19: =(N19*S19)*0.16 -> 0 | AA19: =(N19*0.15)+4.5 -> 4.5 | AB19: =S19*AA19 -> 0 | AC19: =Y19+Z19+AB19+D19 -> #N/A | AD19: =N19*S19 -> 0 | AE19: =AD19-AC19 -> #N/A
A20: 1-19 | B20: =【２】結果!W3 -> 0 | T20: =O20 -> 0 | U20: =(P20*Q20*R20)/5000 -> 0 | V20: =MAX(T20,U20) -> 0 | W20: =CEILING(ROUNDDOWN(V20,2),0.5) -> 0 | X20: =VLOOKUP(W20,送料!$J$3:$K$42,2,FALSE) -> #N/A | Y20: =VLOOKUP(X20,送料!$A$1:$B$40,2,FALSE) -> #N/A | Z20: =(N20*S20)*0.16 -> 0 | AA20: =(N20*0.15)+4.5 -> 4.5 | AB20: =S20*AA20 -> 0 | AC20: =Y20+Z20+AB20+D20 -> #N/A | AD20: =N20*S20 -> 0 | AE20: =AD20-AC20 -> #N/A
A21: 1-20 | B21: =【２】結果!X3 -> 0 | T21: =O21 -> 0 | U21: =(P21*Q21*R21)/5000 -> 0 | V21: =MAX(T21,U21) -> 0 | W21: =CEILING(ROUNDDOWN(V21,2),0.5) -> 0 | X21: =VLOOKUP(W21,送料!$J$3:$K$42,2,FALSE) -> #N/A | Y21: =VLOOKUP(X21,送料!$A$1:$B$40,2,FALSE) -> #N/A | Z21: =(N21*S21)*0.16 -> 0 | AA21: =(N21*0.15)+4.5 -> 4.5 | AB21: =S21*AA21 -> 0 | AC21: =Y21+Z21+AB21+D21 -> #N/A | AD21: =N21*S21 -> 0 | AE21: =AD21-AC21 -> #N/A
A22: 2-1 | B22: =【２】結果!E4 -> 0 | T22: =O22 -> 0 | U22: =(P22*Q22*R22)/5000 -> 0 | V22: =MAX(T22,U22) -> 0 | W22: =CEILING(ROUNDDOWN(V22,2),0.5) -> 0 | X22: =VLOOKUP(W22,送料!$J$3:$K$42,2,FALSE) -> #N/A | Y22: =VLOOKUP(X22,送料!$A$1:$B$40,2,FALSE) -> #N/A | Z22: =(N22*S22)*0.16 -> 0 | AA22: =(N22*0.15)+4.5 -> 4.5 | AB22: =S22*AA22 -> 0 | AC22: =Y22+Z22+AB22+D22 -> #N/A | AD22: =N22*S22 -> 0 | AE22: =AD22-AC22 -> #N/A
A23: 2-2 | B23: =【２】結果!F4 -> 0 | T23: =O23 -> 0 | U23: =(P23*Q23*R23)/5000 -> 0 | V23: =MAX(T23,U23) -> 0 | W23: =CEILING(ROUNDDOWN(V23,2),0.5) -> 0 | X23: =VLOOKUP(W23,送料!$J$3:$K$42,2,FALSE) -> #N/A | Y23: =VLOOKUP(X23,送料!$A$1:$B$40,2,FALSE) -> #N/A | Z23: =(N23*S23)*0.16 -> 0 | AA23: =(N23*0.15)+4.5 -> 4.5 | AB23: =S23*AA23 -> 0 | AC23: =Y23+Z23+AB23+D23 -> #N/A | AD23: =N23*S23 -> 0 | AE23: =AD23-AC23 -> #N/A
A24: 2-3 | B24: =【２】結果!G4 -> 0 | T24: =O24 -> 0 | U24: =(P24*Q24*R24)/5000 -> 0 | V24: =MAX(T24,U24) -> 0 | W24: =CEILING(ROUNDDOWN(V24,2),0.5) -> 0 | X24: =VLOOKUP(W24,送料!$J$3:$K$42,2,FALSE) -> #N/A | Y24: =VLOOKUP(X24,送料!$A$1:$B$40,2,FALSE) -> #N/A | Z24: =(N24*S24)*0.16 -> 0 | AA24: =(N24*0.15)+4.5 -> 4.5 | AB24: =S24*AA24 -> 0 | AC24: =Y24+Z24+AB24+D24 -> #N/A | AD24: =N24*S24 -> 0 | AE24: =AD24-AC24 -> #N/A
A25: 2-4 | B25: =【２】結果!H4 -> 0 | T25: =O25 -> 0 | U25: =(P25*Q25*R25)/5000 -> 0 | V25: =MAX(T25,U25) -> 0 | W25: =CEILING(ROUNDDOWN(V25,2),0.5) -> 0 | X25: =VLOOKUP(W25,送料!$J$3:$K$42,2,FALSE) -> #N/A | Y25: =VLOOKUP(X25,送料!$A$1:$B$40,2,FALSE) -> #N/A | Z25: =(N25*S25)*0.16 -> 0 | AA25: =(N25*0.15)+4.5 -> 4.5 | AB25: =S25*AA25 -> 0 | AC25: =Y25+Z25+AB25+D25 -> #N/A | AD25: =N25*S25 -> 0 | AE25: =AD25-AC25 -> #N/A
A26: 2-5 | B26: =【２】結果!I4 -> 0 | T26: =O26 -> 0 | U26: =(P26*Q26*R26)/5000 -> 0 | V26: =MAX(T26,U26) -> 0 | W26: =CEILING(ROUNDDOWN(V26,2),0.5) -> 0 | X26: =VLOOKUP(W26,送料!$J$3:$K$42,2,FALSE) -> #N/A | Y26: =VLOOKUP(X26,送料!$A$1:$B$40,2,FALSE) -> #N/A | Z26: =(N26*S26)*0.16 -> 0 | AA26: =(N26*0.15)+4.5 -> 4.5 | AB26: =S26*AA26 -> 0 | AC26: =Y26+Z26+AB26+D26 -> #N/A | AD26: =N26*S26 -> 0 | AE26: =AD26-AC26 -> #N/A
A27: 2-6 | B27: =【２】結果!J4 -> 0 | T27: =O27 -> 0 | U27: =(P27*Q27*R27)/5000 -> 0 | V27: =MAX(T27,U27) -> 0 | W27: =CEILING(ROUNDDOWN(V27,2),0.5) -> 0 | X27: =VLOOKUP(W27,送料!$J$3:$K$42,2,FALSE) -> #N/A | Y27: =VLOOKUP(X27,送料!$A$1:$B$40,2,FALSE) -> #N/A | Z27: =(N27*S27)*0.16 -> 0 | AA27: =(N27*0.15)+4.5 -> 4.5 | AB27: =S27*AA27 -> 0 | AC27: =Y27+Z27+AB27+D27 -> #N/A | AD27: =N27*S27 -> 0 | AE27: =AD27-AC27 -> #N/A
A28: 2-7 | B28: =【２】結果!K4 -> 0 | T28: =O28 -> 0 | U28: =(P28*Q28*R28)/5000 -> 0 | V28: =MAX(T28,U28) -> 0 | W28: =CEILING(ROUNDDOWN(V28,2),0.5) -> 0 | X28: =VLOOKUP(W28,送料!$J$3:$K$42,2,FALSE) -> #N/A | Y28: =VLOOKUP(X28,送料!$A$1:$B$40,2,FALSE) -> #N/A | Z28: =(N28*S28)*0.16 -> 0 | AA28: =(N28*0.15)+4.5 -> 4.5 | AB28: =S28*AA28 -> 0 | AC28: =Y28+Z28+AB28+D28 -> #N/A | AD28: =N28*S28 -> 0 | AE28: =AD28-AC28 -> #N/A
A29: 2-8 | B29: =【２】結果!L4 -> 0 | T29: =O29 -> 0 | U29: =(P29*Q29*R29)/5000 -> 0 | V29: =MAX(T29,U29) -> 0 | W29: =CEILING(ROUNDDOWN(V29,2),0.5) -> 0 | X29: =VLOOKUP(W29,送料!$J$3:$K$42,2,FALSE) -> #N/A | Y29: =VLOOKUP(X29,送料!$A$1:$B$40,2,FALSE) -> #N/A | Z29: =(N29*S29)*0.16 -> 0 | AA29: =(N29*0.15)+4.5 -> 4.5 | AB29: =S29*AA29 -> 0 | AC29: =Y29+Z29+AB29+D29 -> #N/A | AD29: =N29*S29 -> 0 | AE29: =AD29-AC29 -> #N/A
A30: 2-9 | B30: =【２】結果!M4 -> 0 | T30: =O30 -> 0 | U30: =(P30*Q30*R30)/5000 -> 0 | V30: =MAX(T30,U30) -> 0 | W30: =CEILING(ROUNDDOWN(V30,2),0.5) -> 0 | X30: =VLOOKUP(W30,送料!$J$3:$K$42,2,FALSE) -> #N/A | Y30: =VLOOKUP(X30,送料!$A$1:$B$40,2,FALSE) -> #N/A | Z30: =(N30*S30)*0.16 -> 0 | AA30: =(N30*0.15)+4.5 -> 4.5 | AB30: =S30*AA30 -> 0 | AC30: =Y30+Z30+AB30+D30 -> #N/A | AD30: =N30*S30 -> 0 | AE30: =AD30-AC30 -> #N/A
A31: 2-10 | B31: =【２】結果!N4 -> 0 | T31: =O31 -> 0 | U31: =(P31*Q31*R31)/5000 -> 0 | V31: =MAX(T31,U31) -> 0 | W31: =CEILING(ROUNDDOWN(V31,2),0.5) -> 0 | X31: =VLOOKUP(W31,送料!$J$3:$K$42,2,FALSE) -> #N/A | Y31: =VLOOKUP(X31,送料!$A$1:$B$40,2,FALSE) -> #N/A | Z31: =(N31*S31)*0.16 -> 0 | AA31: =(N31*0.15)+4.5 -> 4.5 | AB31: =S31*AA31 -> 0 | AC31: =Y31+Z31+AB31+D31 -> #N/A | AD31: =N31*S31 -> 0 | AE31: =AD31-AC31 -> #N/A
A32: 2-11 | B32: =【２】結果!O4 -> 0 | T32: =O32 -> 0 | U32: =(P32*Q32*R32)/5000 -> 0 | V32: =MAX(T32,U32) -> 0 | W32: =CEILING(ROUNDDOWN(V32,2),0.5) -> 0 | X32: =VLOOKUP(W32,送料!$J$3:$K$42,2,FALSE) -> #N/A | Y32: =VLOOKUP(X32,送料!$A$1:$B$40,2,FALSE) -> #N/A | Z32: =(N32*S32)*0.16 -> 0 | AA32: =(N32*0.15)+4.5 -> 4.5 | AB32: =S32*AA32 -> 0 | AC32: =Y32+Z32+AB32+D32 -> #N/A | AD32: =N32*S32 -> 0 | AE32: =AD32-AC32 -> #N/A
A33: 2-12 | B33: =【２】結果!P4 -> 0 | T33: =O33 -> 0 | U33: =(P33*Q33*R33)/5000 -> 0 | V33: =MAX(T33,U33) -> 0 | W33: =CEILING(ROUNDDOWN(V33,2),0.5) -> 0 | X33: =VLOOKUP(W33,送料!$J$3:$K$42,2,FALSE) -> #N/A | Y33: =VLOOKUP(X33,送料!$A$1:$B$40,2,FALSE) -> #N/A | Z33: =(N33*S33)*0.16 -> 0 | AA33: =(N33*0.15)+4.5 -> 4.5 | AB33: =S33*AA33 -> 0 | AC33: =Y33+Z33+AB33+D33 -> #N/A | AD33: =N33*S33 -> 0 | AE33: =AD33-AC33 -> #N/A
A34: 2-13 | B34: =【２】結果!Q4 -> 0 | T34: =O34 -> 0 | U34: =(P34*Q34*R34)/5000 -> 0 | V34: =MAX(T34,U34) -> 0 | W34: =CEILING(ROUNDDOWN(V34,2),0.5) -> 0 | X34: =VLOOKUP(W34,送料!$J$3:$K$42,2,FALSE) -> #N/A | Y34: =VLOOKUP(X34,送料!$A$1:$B$40,2,FALSE) -> #N/A | Z34: =(N34*S34)*0.16 -> 0 | AA34: =(N34*0.15)+4.5 -> 4.5 | AB34: =S34*AA34 -> 0 | AC34: =Y34+Z34+AB34+D34 -> #N/A | AD34: =N34*S34 -> 0 | AE34: =AD34-AC34 -> #N/A
A35: 2-14 | B35: =【２】結果!R4 -> 0 | T35: =O35 -> 0 | U35: =(P35*Q35*R35)/5000 -> 0 | V35: =MAX(T35,U35) -> 0 | W35: =CEILING(ROUNDDOWN(V35,2),0.5) -> 0 | X35: =VLOOKUP(W35,送料!$J$3:$K$42,2,FALSE) -> #N/A | Y35: =VLOOKUP(X35,送料!$A$1:$B$40,2,FALSE) -> #N/A | Z35: =(N35*S35)*0.16 -> 0 | AA35: =(N35*0.15)+4.5 -> 4.5 | AB35: =S35*AA35 -> 0 | AC35: =Y35+Z35+AB35+D35 -> #N/A | AD35: =N35*S35 -> 0 | AE35: =AD35-AC35 -> #N/A
A36: 2-15 | B36: =【２】結果!S4 -> 0 | T36: =O36 -> 0 | U36: =(P36*Q36*R36)/5000 -> 0 | V36: =MAX(T36,U36) -> 0 | W36: =CEILING(ROUNDDOWN(V36,2),0.5) -> 0 | X36: =VLOOKUP(W36,送料!$J$3:$K$42,2,FALSE) -> #N/A | Y36: =VLOOKUP(X36,送料!$A$1:$B$40,2,FALSE) -> #N/A | Z36: =(N36*S36)*0.16 -> 0 | AA36: =(N36*0.15)+4.5 -> 4.5 | AB36: =S36*AA36 -> 0 | AC36: =Y36+Z36+AB36+D36 -> #N/A | AD36: =N36*S36 -> 0 | AE36: =AD36-AC36 -> #N/A
A37: 2-16 | B37: =【２】結果!T4 -> 0 | T37: =O37 -> 0 | U37: =(P37*Q37*R37)/5000 -> 0 | V37: =MAX(T37,U37) -> 0 | W37: =CEILING(ROUNDDOWN(V37,2),0.5) -> 0 | X37: =VLOOKUP(W37,送料!$J$3:$K$42,2,FALSE) -> #N/A | Y37: =VLOOKUP(X37,送料!$A$1:$B$40,2,FALSE) -> #N/A | Z37: =(N37*S37)*0.16 -> 0 | AA37: =(N37*0.15)+4.5 -> 4.5 | AB37: =S37*AA37 -> 0 | AC37: =Y37+Z37+AB37+D37 -> #N/A | AD37: =N37*S37 -> 0 | AE37: =AD37-AC37 -> #N/A
A38: 2-17 | B38: =【２】結果!U4 -> 0 | T38: =O38 -> 0 | U38: =(P38*Q38*R38)/5000 -> 0 | V38: =MAX(T38,U38) -> 0 | W38: =CEILING(ROUNDDOWN(V38,2),0.5) -> 0 | X38: =VLOOKUP(W38,送料!$J$3:$K$42,2,FALSE) -> #N/A | Y38: =VLOOKUP(X38,送料!$A$1:$B$40,2,FALSE) -> #N/A | Z38: =(N38*S38)*0.16 -> 0 | AA38: =(N38*0.15)+4.5 -> 4.5 | AB38: =S38*AA38 -> 0 | AC38: =Y38+Z38+AB38+D38 -> #N/A | AD38: =N38*S38 -> 0 | AE38: =AD38-AC38 -> #N/A
A39: 2-18 | B39: =【２】結果!V4 -> 0 | T39: =O39 -> 0 | U39: =(P39*Q39*R39)/5000 -> 0 | V39: =MAX(T39,U39) -> 0 | W39: =CEILING(ROUNDDOWN(V39,2),0.5) -> 0 | X39: =VLOOKUP(W39,送料!$J$3:$K$42,2,FALSE) -> #N/A | Y39: =VLOOKUP(X39,送料!$A$1:$B$40,2,FALSE) -> #N/A | Z39: =(N39*S39)*0.16 -> 0 | AA39: =(N39*0.15)+4.5 -> 4.5 | AB39: =S39*AA39 -> 0 | AC39: =Y39+Z39+AB39+D39 -> #N/A | AD39: =N39*S39 -> 0 | AE39: =AD39-AC39 -> #N/A
A40: 2-19 | B40: =【２】結果!W4 -> 0 | T40: =O40 -> 0 | U40: =(P40*Q40*R40)/5000 -> 0 | V40: =MAX(T40,U40) -> 0 | W40: =CEILING(ROUNDDOWN(V40,2),0.5) -> 0 | X40: =VLOOKUP(W40,送料!$J$3:$K$42,2,FALSE) -> #N/A | Y40: =VLOOKUP(X40,送料!$A$1:$B$40,2,FALSE) -> #N/A | Z40: =(N40*S40)*0.16 -> 0 | AA40: =(N40*0.15)+4.5 -> 4.5 | AB40: =S40*AA40 -> 0 | AC40: =Y40+Z40+AB40+D40 -> #N/A | AD40: =N40*S40 -> 0 | AE40: =AD40-AC40 -> #N/A
...

Sheet 【４】精査
B1: 日本語タイトル | C1: 仕入れ先価格 | D1: 予想 最安値($) | E1: 結果（Fedex） | F1: 予想送料 | G1: 予想手数料 | H1: 予想関税2 | I1: 仕入れ先候補 | J1: 抽出URL | K1: 安仕入れ先１ | L1: 安仕入れ先２ | M1: 安仕入れ先３ | N1: 安仕入れ先４ | O1: 安仕入れ先５ | P1: メルカリ | Q1: ラクマ | R1: 楽天市場 | S1: ヤフオク | T1: ヤフーショッピング | U1: チェック | V1: 出品テンプレート | AB1: 出品テンプレート一覧
A2: 1 | AB2: Beauty Light Therapy
A3: 2 | AB3: Books
A4: 3 | AB4: CCG Individual Cards
A5: 4 | AB5: CDs
A6: 5 | AB6: Ceramic ornaments & Statue
A7: 6 | AB7: Dolls & Dolls playsets
A8: 7 | AB8: DVD & Blu-ray
A9: 8 | AB9: Eyeglass Frames
A10: 9 | AB10: Fish Binders
A11: 10 | AB11: Model Kits Hobby Toy
A12: 11 | AB12: Music Instrument
A13: 12 | AB13: Other Animation Merchandise
... A25: 24 | AB25: Wristwatches
A26: 25
A27: 26
A28: 27
A29: 28
A30: 29
A31: 30
A32: 31
A33: 32
A34: 33
A35: 34
A36: 35
A37: 36
... A201: 200

Sheet 【５】出品リスト
B1: Item title | C1: Custom label (SKU) | D1: Shipping Policy | E1: カテゴリ（出品テンプレート参照） | F1: 出品価格 | G1: 仕入れ先 | H1: 画像
A2: File1 | B2: Galaxy Express 999 The Movie 4K UHD Blu-ray Box Set Leiji Matsumoto Anime Japan | C2: 1658 | D2: Fedex 2.5kg | E2: DVD & Blu-ray | F2: 620 | G2: https://jp.mercari.com/item/m27984414731 | H2: 仕入れ先からダウンロードしてください
A3: File2 | B3: Kingdom Hearts 20th Anniversary Plate Collection Complete Set 16 Types Japan | C3: 1659 | D3: Fedex 2.5kg | E3: Other Animation Merchandise | F3: 274.99 | G3: https://jp.mercari.com/item/m80942673010 | H3: 仕入れ先からダウンロードしてください
A4: File3 | B4: Kingdom Hearts x Samantha Thavasa 20th Round Zip Leather Long Wallet Japan | C4: 1660 | D4: Fedex 1.0kg | E4: Other Animation Merchandise | F4: 755.99 | G4: https://auctions.yahoo.co.jp/jp/auction/r1175870416 | H4: 仕入れ先からダウンロードしてください
A5: File4 | B5: Volks Super Dollfie Seikan Gakuryo Eric SD17 Boy Doll Full Set Japan | C5: 1661 | D5: Fedex 5.5kg | E5: Dolls & Dolls playsets | F5: 1039.99 | G5: https://page.auctions.yahoo.co.jp/jp/auction/p1231976907 | H5: 仕入れ先からダウンロードしてください
A6: File5 | B6: Volks Dollfie Dream Sister DDS Macross F Ranka Lee Doll New Sealed Japan | C6: 1662 | D6: Fedex 5.5kg | E6: Dolls & Dolls playsets | F6: 1000.99 | G6: https://page.auctions.yahoo.co.jp/jp/auction/d516061039 | H6: 仕入れ先からダウンロードしてください
A7: File6 | B7: Toshi Yoshida Monument Valley Woodblock Print 1971 Framed Shin-hanga Japan | C7: 1663 | D7: Fedex 2.5kg | E7: Other Animation Merchandise | F7: 1250.99 | G7: https://page.auctions.yahoo.co.jp/jp/auction/p1231857857 | H7: 仕入れ先からダウンロードしてください
A8: File7 | B8: AUTOart 1/43 Mad Max 2 Interceptor & Enemy Car Weathering Diecast Set Limited | C8: 1664 | D8: Fedex 2.0kg | E8: Other Animation Merchandise | F8: 592 | G8: https://jp.mercari.com/item/m24175944612 | H8: 仕入れ先からダウンロードしてください
A9: File8 | B9: Aoshima 1/24 Mad Max 2 The Road Warrior Interceptor Model Kit Supercharger Japan | C9: 1665 | D9: Fedex 2.0kg | E9: Other Animation Merchandise | F9: 419 | G9: https://jp.mercari.com/item/m64753601502 | H9: 仕入れ先からダウンロードしてください
A10: File9 | B10: Mad Max Interceptor Mel Gibson 1/6 Figure Premium Toys Westland Rare Japan | C10: 1666 | D10: Fedex 2.0kg | E10: Other Animation Merchandise | F10: 809 | G10: https://paypayfleamarket.yahoo.co.jp/item/z623953652 | H10: 仕入れ先からダウンロードしてください
A11: File10 | B11: Bloodborne T-Shirt Father Gascoigne TORCH TORCH Size WM Heather Grey New Japan | C11: 1667 | D11: Fedex 1.5kg | E11: Other Animation Merchandise | F11: 294 | G11: https://jp.mercari.com/item/m50698842813 | H11: 仕入れ先からダウンロードしてください
A12: File11 | B12: Bloodborne T-Shirt Micolash Host of Nightmare TORCH TORCH Size WM Black Japan | C12: 1668 | D12: Fedex 1.5kg | E12: Other Animation Merchandise | F12: 294 | G12: https://jp.mercari.com/item/m27046971593 | H12: 仕入れ先からダウンロードしてください
A13: File12 | B13: Swatch MoMA Tadanori Yokoo SUOZ334 The City and Design Art Wrist Watch Japan | C13: 1669 | D13: Fedex 0.5kg | E13: Other Animation Merchandise | F13: 250 | G13: https://jp.mercari.com/item/m29601124354 | H13: 仕入れ先からダウンロードしてください
... A41: File40 | B41: Ghibli Acapella Style CD Studio Ghibli Songs Teichiku Japan Totoro Spirited Away | C41: 1697 | D41: Fedex 1.0kg | E41: Fish Binders | F41: 229 | G41: https://paypayfleamarket.yahoo.co.jp/item/z300604720 | H41: 仕入れ先からダウンロードしてください
A42: File41 | B42: Shimano Furuno Tankenmaru CV Color Fish Finder Sounder Marine Japan | C42: 1698 | D42: Fedex 3.0kg | F42: 399 | G42: https://jp.mercari.com/item/m61432143703 | H42: 仕入れ先からダウンロードしてください
A43: File42 | B43: Medicom RAH Metal Gear Solid 3 Snake Eater Naked Snake WF2005 500 Limited | C43: 1699 | D43: Fedex 3.0kg | E43: Other Animation Merchandise | F43: 520 | G43: https://jp.mercari.com/item/m43750621893 | H43: 仕入れ先からダウンロードしてください
A44: File43 | B44: Brahms Complete Edition 46 CD Box Deutsche Grammophon Karajan Pollini Abbado | C44: 1700 | D44: Fedex 1.5kg | E44: CDs | F44: 298 | G44: https://jp.mercari.com/item/m48839020184 | H44: 仕入れ先からダウンロードしてください
A45: File44 | B45: SIREN x Doko Demo Issyo Shibito-ro T-Shirt 2014 Original Cospa Size L Japan | C45: 1701 | D45: Fedex 2.0kg | E45: Other Animation Merchandise | F45: 270 | G45: https://jp.mercari.com/item/m73428428037 | H45: 仕入れ先からダウンロードしてください
A46: File45 | B46: Vertex Super Pochaco Cowgirl 1/6 Figure WonderFestival Limited Edition Japan | C46: 1702 | D46: Fedex 5.0kg | E46: Other Animation Merchandise | F46: 490 | G46: https://jp.mercari.com/item/m25397753764 | H46: 仕入れ先からダウンロードしてください
A47: File46 | B47: Medicos Chozokado Guido Mista and Sex Pistols JoJo Part 5 Figure Reissue | C47: 1703 | D47: Fedex 1.0kg | E47: Other Animation Merchandise | F47: 228 | G47: https://jp.mercari.com/shops/product/2JUYTDGc3URDspDQNQUZPn | H47: 仕入れ先からダウンロードしてください
A48: File47 | B48: Alpha Industries x Ace Combat 7 CWU-36/P Flight Jacket Black Size XL Japan | C48: 1704 | D48: Fedex 7.5kg | E48: Trading Card Singles | F48: 920 | G48: https://page.auctions.yahoo.co.jp/jp/auction/b1236905956 | H48: 仕入れ先からダウンロードしてください
A49: File48 | B49: Hazbin Hotel The Roach Secret Trading Card 64/60 Season 2 | C49: 1705 | D49: Fedex 0.5kg | F49: 560 | G49: https://jp.mercari.com/item/m81328910059 | H49: 仕入れ先からダウンロードしてください
A50: File49 | B50: Hazbin Hotel Charlie Acrylic Stand Standee Shark Robot Limited Japan | C50: 1706 | D50: Fedex 0.5kg | E50: Books | F50: 980 | G50: https://jp.mercari.com/item/m69186539344 | H50: 仕入れ先からダウンロードしてください
A51: File50 | B51: ARS MAGNA Yukito Kishiro First Art Book Battle Angel Alita 145 Illustrations | C51: 1707 | D51: Fedex 1.5kg | F51: 227 | G51: https://jp.mercari.com/item/m35148971723 | H51: 仕入れ先からダウンロードしてください
A52: File51 | B52: Neo Blythe Winterish Allure Doll Takara Tomy 2015 Sealed Japan | C52: 1708 | D52: Fedex 1.5kg | E52: Dolls & Dolls playsets | F52: 420 | G52: https://jp.mercari.com/item/m31653145904 | H52: 仕入れ先からダウンロードしてください
A53: File52 | B53: Soul of Chogokin GX-05 Daiku Maryu Gaiking Bandai Diecast Figure Japan | C53: 1709 | D53: Fedex 4.5kg | E53: Other Animation Merchandise | F53: 440 | G53: https://auctions.yahoo.co.jp/jp/auction/o1239092692 | H53: 仕入れ先からダウンロードしてください
A54: File53 | B54: KISS Retro 12 inch Figure Set with Mini Concert T-Shirts Vintage | C54: 1710 | D54: Fedex 1.0kg | E54: Other Animation Merchandise | F54: 640 | G54: https://auctions.yahoo.co.jp/jp/auction/c1058697225 | H54: 仕入れ先からダウンロードしてください
A55: File54 | B55: Bandai Chogokin GD-57B Mechagodzilla 2004 Black Version Tokyo SOS Japan | C55: 1711 | D55: Fedex 2.0kg | E55: Other Animation Merchandise | F55: 193 | G55: https://jp.mercari.com/shops/product/2JUGr6vHSnR9SpPJDpUFby | H55: 仕入れ先からダウンロードしてください
A56: File55 | B56: Popy Chogokin Mechagodzilla Vintage Diecast Figure Japan | C56: 1712 | D56: Fedex 1.5kg | E56: Other Animation Merchandise | F56: 880 | G56: https://jp.mercari.com/shops/product/2JMbWsRLdJeksEgW8dhoeZ | H56: 仕入れ先からダウンロードしてください
A57: File56 | B57: Max Factory I-No Extra Color Ver Guilty Gear XX 1/7 Figure WF2008 Limited | C57: 1713 | D57: Fedex 4.5kg | E57: Other Animation Merchandise | F57: 427 | G57: https://jp.mercari.com/item/m14829633369 | H57: 仕入れ先からダウンロードしてください
A58: File57 | B58: Harem in the Labyrinth Roxanne Hyoju Issei Comic Ver 1/7 Figure Japan | C58: 1714 | D58: Fedex 1.5kg | E58: Other Animation Merchandise | F58: 372 | G58: https://jp.mercari.com/item/m61827929822 | H58: 仕入れ先からダウンロードしてください
A59: File58 | B59: Realize Garage Kit Manami and Roxanne Resin Figure 2 Set K.PIERO Unbuilt | C59: 1715 | D59: Fedex 1.5kg | E59: Other Animation Merchandise | F59: 286 | G59: https://jp.mercari.com/item/m11658788348 | H59: 仕入れ先からダウンロードしてください
A60: File59 | B60: Shohei Ohtani Package Sleeve PS4 PS5 Powerpro 2024-2025 Bonus | C60: 1716 | D60: Fedex 0.5kg | E60: Other Animation Merchandise | F60: 1053 | G60: https://paypayfleamarket.yahoo.co.jp/item/z647477800 | H60: 仕入れ先からダウンロードしてください
A61: File60 | B61: Sentinel RIOBOT Getter 1 Devolution and Upgrade Parts Set Figure Japan | C61: 1717 | D61: Fedex 2.0kg | E61: Other Animation Merchandise | F61: 950 | G61: https://jp.mercari.com/item/m14135353857 | H61: 仕入れ先からダウンロードしてください
A62: File61 | B62: Bungo Stray Dogs Dazai Osamu F:NEX 1/7 Figure FuRyu Made to Order Tuxedo | C62: 1718 | D62: Fedex 1.5kg | E62: Other Animation Merchandise | F62: 922 | G62: https://jp.mercari.com/item/m84715579311 | H62: 仕入れ先からダウンロードしてください
A63: File62 | B63: Bungo Stray Dogs Nakahara Chuya 1/7 Figure Tuxedo F:NEX Event Ver Japan | C63: 1719 | D63: Fedex 1.5kg | E63: Other Animation Merchandise | F63: 922 | G63: https://jp.mercari.com/item/m14231022758 | H63: 仕入れ先からダウンロードしてください
... A235: File234 | B235: The Kinks At The BBC SHM-CD BOX 5CD 1DVD Limited Japan Discontinued Sealed New | C235: 1891 | D235: Fedex 1.0kg | E235: CDs | F235: 430 | G235: https://jp.mercari.com/item/m56334718647 | H235: 仕入れ先からダウンロードしてください

Sheet 【６】管理用
A1: Custom label (SKU) | B1: 商品名 | C1: 在庫数 | D1: 仕入価格 | E1: 販売価格 | F1: 見込送料 | G1: ebay相場 | H1: 最安値1 | I1: 最安値2 | J1: 最安値3 | K1: 最安値4 | L1: 最安値5 | N1: メルカリ | O1: ラクマ | P1: 楽天市場 | Q1: ヤフオク | R1: ヤフーショッピング
A2: 1658 | B2: 銀河鉄道999 THE MOVIE 4KリマスターBOX | C2: 1 | D2: 41200 | E2: 620 | F2: Fedex 2.5kg | G2: https://www.ebay.com/sch/i.html?_nkw=Galaxy+Express+999+The+Movie+4K+Remaster+Box+Blu-ray+First+Limited&_sacat=0&_from=R40&_sop=15&rt=nc&_udlo=20000 | H2: https://jp.mercari.com/item/m27984414731 | I2: https://jp.mercari.com/item/m58252217206 | N2: https://jp.mercari.com/search?keyword=%E9%8A%80%E6%B2%B3%E9%89%84%E9%81%93999%204K%E3%83%AA%E3%83%9E%E3%82%B9%E3%82%BF%E3%83%BCBOX&price_min=10000&sort=price&order=asc&status=on_sale | O2: https://fril.jp/s?query=%E9%8A%80%E6%B2%B3%E9%89%84%E9%81%93999%204K%E3%83%AA%E3%83%9E%E3%82%B9%E3%82%BF%E3%83%BCBOX&min=10000&transaction=selling | P2: https://search.rakuten.co.jp/search/mall/%E9%8A%80%E6%B2%B3%E9%89%84%E9%81%93999%204K%E3%83%AA%E3%83%9E%E3%82%B9%E3%82%BF%E3%83%BCBOX/?min=10000 | Q2: https://auctions.yahoo.co.jp/search/search?p=%E9%8A%80%E6%B2%B3%E9%89%84%E9%81%93999%204K%E3%83%AA%E3%83%9E%E3%82%B9%E3%82%BF%E3%83%BCBOX&aucminprice=10000 | R2: https://shopping.yahoo.co.jp/search/%E9%8A%80%E6%B2%B3%E9%89%84%E9%81%93999%204K%E3%83%AA%E3%83%9E%E3%82%B9%E3%82%BF%E3%83%BCBOX/0/?pf=10000
A3: 1659 | B3: キングダムハーツ プレートコレクション 全16種 フルコンプ | C3: 1 | D3: 13800 | E3: 274 | F3: Fedex 2.5kg | G3: https://www.ebay.com/sch/i.html?_nkw=Kingdom%20Hearts%20Plate%20Collection%20Complete%2016%20Set&_sacat=0&_from=R40&_sop=15&rt=nc&_udlo=20000 | H3: https://jp.mercari.com/item/m80942673010 | I3: https://jp.mercari.com/search?keyword=%E3%82%AD%E3%83%B3%E3%82%B0%E3%83%80%E3%83%A0%E3%83%8F%E3%83%BC%E3%83%84%20%E3%83%97%E3%83%AC%E3%83%BC%E3%83%88%E3%82%B3%E3%83%AC%E3%82%AF%E3%82%B7%E3%83%A7%E3%83%B3&price_min=10000&sort=price&order=asc&status=on_sale | J3: https://jp.mercari.com/search?keyword=%E3%82%AD%E3%83%B3%E3%82%B0%E3%83%80%E3%83%A0%E3%83%8F%E3%83%BC%E3%83%84%20%E3%83%97%E3%83%AC%E3%83%BC%E3%83%88%E3%82%B3%E3%83%AC%E3%82%AF%E3%82%B7%E3%83%A7%E3%83%B3&price_min=10000&sort=price&order=asc&status=on_sale | K3: https://jp.mercari.com/search?keyword=%E3%82%AD%E3%83%B3%E3%82%B0%E3%83%80%E3%83%A0%E3%83%8F%E3%83%BC%E3%83%84%20%E3%83%97%E3%83%AC%E3%83%BC%E3%83%88%E3%82%B3%E3%83%AC%E3%82%AF%E3%82%B7%E3%83%A7%E3%83%B3&price_min=10000&sort=price&order=asc&status=on_sale | L3: https://jp.mercari.com/search?keyword=%E3%82%AD%E3%83%B3%E3%82%B0%E3%83%80%E3%83%A0%E3%83%8F%E3%83%BC%E3%83%84%20%E3%83%97%E3%83%AC%E3%83%BC%E3%83%88%E3%82%B3%E3%83%AC%E3%82%AF%E3%82%B7%E3%83%A7%E3%83%B3&price_min=10000&sort=price&order=asc&status=on_sale | N3: https://jp.mercari.com/search?keyword=%E3%82%AD%E3%83%B3%E3%82%B0%E3%83%80%E3%83%A0%E3%83%8F%E3%83%BC%E3%83%84%20%E3%83%97%E3%83%AC%E3%83%BC%E3%83%88%E3%82%B3%E3%83%AC%E3%82%AF%E3%82%B7%E3%83%A7%E3%83%B3&price_min=10000&sort=price&order=asc&status=on_sale | O3: https://fril.jp/s?query=%E3%82%AD%E3%83%B3%E3%82%B0%E3%83%80%E3%83%A0%E3%83%8F%E3%83%BC%E3%83%84%20%E3%83%97%E3%83%AC%E3%83%BC%E3%83%88%E3%82%B3%E3%83%AC%E3%82%AF%E3%82%B7%E3%83%A7%E3%83%B3&min=10000&transaction=selling | P3: https://search.rakuten.co.jp/search/mall/%E3%82%AD%E3%83%B3%E3%82%B0%E3%83%80%E3%83%A0%E3%83%8F%E3%83%BC%E3%83%84%20%E3%83%97%E3%83%AC%E3%83%BC%E3%83%88%E3%82%B3%E3%83%AC%E3%82%AF%E3%82%B7%E3%83%A7%E3%83%B3/?min=10000 | Q3: https://auctions.yahoo.co.jp/search/search?p=%E3%82%AD%E3%83%B3%E3%82%B0%E3%83%80%E3%83%A0%E3%83%8F%E3%83%BC%E3%83%84%20%E3%83%97%E3%83%AC%E3%83%BC%E3%83%88%E3%82%B3%E3%83%AC%E3%82%AF%E3%82%B7%E3%83%A7%E3%83%B3&aucminprice=10000 | R3: https://shopping.yahoo.co.jp/search/%E3%82%AD%E3%83%B3%E3%82%B0%E3%83%80%E3%83%A0%E3%83%8F%E3%83%BC%E3%83%84%20%E3%83%97%E3%83%AC%E3%83%BC%E3%83%88%E3%82%B3%E3%83%AC%E3%82%AF%E3%82%B7%E3%83%A7%E3%83%B3/0/?pf=10000
A4: 1660 | B4: サマンサタバサ キングダムハーツ 20周年 ラウンドジップ財布 | C4: 1 | D4: 59999 | E4: 755 | F4: Fedex 1.0kg | G4: https://www.ebay.com/sch/i.html?_nkw=Samantha%20Thavasa%20Kingdom%20Hearts%2020th%20Round%20Zip%20Wallet&_sacat=0&_from=R40&_sop=15&rt=nc&_udlo=20000 | H4: https://auctions.yahoo.co.jp/jp/auction/r1175870416 | I4: https://jp.mercari.com/search?keyword=%E3%82%B5%E3%83%9E%E3%83%B3%E3%82%B5%E3%82%BF%E3%83%90%E3%82%B5%20%E3%82%AD%E3%83%B3%E3%82%B0%E3%83%80%E3%83%A0%E3%83%8F%E3%83%BC%E3%83%84%20%E8%B2%A1%E5%B8%83&price_min=10000&sort=price&order=asc&status=on_sale | J4: https://jp.mercari.com/search?keyword=%E3%82%B5%E3%83%9E%E3%83%B3%E3%82%B5%E3%82%BF%E3%83%90%E3%82%B5%20%E3%82%AD%E3%83%B3%E3%82%B0%E3%83%80%E3%83%A0%E3%83%8F%E3%83%BC%E3%83%84%20%E8%B2%A1%E5%B8%83&price_min=10000&sort=price&order=asc&status=on_sale | K4: https://jp.mercari.com/search?keyword=%E3%82%B5%E3%83%9E%E3%83%B3%E3%82%B5%E3%82%BF%E3%83%90%E3%82%B5%20%E3%82%AD%E3%83%B3%E3%82%B0%E3%83%80%E3%83%A0%E3%83%8F%E3%83%BC%E3%83%84%20%E8%B2%A1%E5%B8%83&price_min=10000&sort=price&order=asc&status=on_sale | L4: https://jp.mercari.com/search?keyword=%E3%82%B5%E3%83%9E%E3%83%B3%E3%82%B5%E3%82%BF%E3%83%90%E3%82%B5%20%E3%82%AD%E3%83%B3%E3%82%B0%E3%83%80%E3%83%A0%E3%83%8F%E3%83%BC%E3%83%84%20%E8%B2%A1%E5%B8%83&price_min=10000&sort=price&order=asc&status=on_sale | N4: https://jp.mercari.com/search?keyword=%E3%82%B5%E3%83%9E%E3%83%B3%E3%82%B5%E3%82%BF%E3%83%90%E3%82%B5%20%E3%82%AD%E3%83%B3%E3%82%B0%E3%83%80%E3%83%A0%E3%83%8F%E3%83%BC%E3%83%84%20%E8%B2%A1%E5%B8%83&price_min=10000&sort=price&order=asc&status=on_sale | O4: https://fril.jp/s?query=%E3%82%B5%E3%83%9E%E3%83%B3%E3%82%B5%E3%82%BF%E3%83%90%E3%82%B5%20%E3%82%AD%E3%83%B3%E3%82%B0%E3%83%80%E3%83%A0%E3%83%8F%E3%83%BC%E3%83%84%20%E8%B2%A1%E5%B8%83&min=10000&transaction=selling | P4: https://search.rakuten.co.jp/search/mall/%E3%82%B5%E3%83%9E%E3%83%B3%E3%82%B5%E3%82%BF%E3%83%90%E3%82%B5%20%E3%82%AD%E3%83%B3%E3%82%B0%E3%83%80%E3%83%A0%E3%83%8F%E3%83%BC%E3%83%84%20%E8%B2%A1%E5%B8%83/?min=10000 | Q4: https://auctions.yahoo.co.jp/search/search?p=%E3%82%B5%E3%83%9E%E3%83%B3%E3%82%B5%E3%82%BF%E3%83%90%E3%82%B5%20%E3%82%AD%E3%83%B3%E3%82%B0%E3%83%80%E3%83%A0%E3%83%8F%E3%83%BC%E3%83%84%20%E8%B2%A1%E5%B8%83&aucminprice=10000 | R4: https://shopping.yahoo.co.jp/search/%E3%82%B5%E3%83%9E%E3%83%B3%E3%82%B5%E3%82%BF%E3%83%90%E3%82%B5%20%E3%82%AD%E3%83%B3%E3%82%B0%E3%83%80%E3%83%A0%E3%83%8F%E3%83%BC%E3%83%84%20%E8%B2%A1%E5%B8%83/0/?pf=10000
A5: 1661 | B5: スーパードルフィー 星間学寮 エリック | C5: 1 | D5: 92000 | E5: 1039 | F5: Fedex 5.5kg | G5: https://www.ebay.com/sch/i.html?_nkw=Volks%20Super%20Dollfie%20Seikan%20Gakuryo%20Eric%20Doll&_sacat=0&_from=R40&_sop=15&rt=nc&_udlo=20000 | H5: https://page.auctions.yahoo.co.jp/jp/auction/p1231976907 | I5: https://jp.mercari.com/search?keyword=%E3%82%B9%E3%83%BC%E3%83%91%E3%83%BC%E3%83%89%E3%83%AB%E3%83%95%E3%82%A3%E3%83%BC%20%E3%82%A8%E3%83%AA%E3%83%83%E3%82%AF&price_min=10000&sort=price&order=asc&status=on_sale | J5: https://jp.mercari.com/search?keyword=%E3%82%B9%E3%83%BC%E3%83%91%E3%83%BC%E3%83%89%E3%83%AB%E3%83%95%E3%82%A3%E3%83%BC%20%E3%82%A8%E3%83%AA%E3%83%83%E3%82%AF&price_min=10000&sort=price&order=asc&status=on_sale | K5: https://jp.mercari.com/search?keyword=%E3%82%B9%E3%83%BC%E3%83%91%E3%83%BC%E3%83%89%E3%83%AB%E3%83%95%E3%82%A3%E3%83%BC%20%E3%82%A8%E3%83%AA%E3%83%83%E3%82%AF&price_min=10000&sort=price&order=asc&status=on_sale | L5: https://jp.mercari.com/search?keyword=%E3%82%B9%E3%83%BC%E3%83%91%E3%83%BC%E3%83%89%E3%83%AB%E3%83%95%E3%82%A3%E3%83%BC%20%E3%82%A8%E3%83%AA%E3%83%83%E3%82%AF&price_min=10000&sort=price&order=asc&status=on_sale | N5: https://jp.mercari.com/search?keyword=%E3%82%B9%E3%83%BC%E3%83%91%E3%83%BC%E3%83%89%E3%83%AB%E3%83%95%E3%82%A3%E3%83%BC%20%E3%82%A8%E3%83%AA%E3%83%83%E3%82%AF&price_min=10000&sort=price&order=asc&status=on_sale | O5: https://fril.jp/s?query=%E3%82%B9%E3%83%BC%E3%83%91%E3%83%BC%E3%83%89%E3%83%AB%E3%83%95%E3%82%A3%E3%83%BC%20%E3%82%A8%E3%83%AA%E3%83%83%E3%82%AF&min=10000&transaction=selling | P5: https://search.rakuten.co.jp/search/mall/%E3%82%B9%E3%83%BC%E3%83%91%E3%83%BC%E3%83%89%E3%83%AB%E3%83%95%E3%82%A3%E3%83%BC%20%E3%82%A8%E3%83%AA%E3%83%83%E3%82%AF/?min=10000 | Q5: https://auctions.yahoo.co.jp/search/search?p=%E3%82%B9%E3%83%BC%E3%83%91%E3%83%BC%E3%83%89%E3%83%AB%E3%83%95%E3%82%A3%E3%83%BC%20%E3%82%A8%E3%83%AA%E3%83%83%E3%82%AF&aucminprice=10000 | R5: https://shopping.yahoo.co.jp/search/%E3%82%B9%E3%83%BC%E3%83%91%E3%83%BC%E3%83%89%E3%83%AB%E3%83%95%E3%82%A3%E3%83%BC%20%E3%82%A8%E3%83%AA%E3%83%83%E3%82%AF/0/?pf=10000
A6: 1662 | B6: ボークス ドルフィードリーム DDS マクロスF ランカ・リー | C6: 1 | D6: 88000 | E6: 1000 | F6: Fedex 5.5kg | G6: https://www.ebay.com/sch/i.html?_nkw=Volks%20Dollfie%20Dream%20DDS%20Macross%20F%20Ranka%20Lee&_sacat=0&_from=R40&_sop=15&rt=nc&_udlo=20000 | H6: https://page.auctions.yahoo.co.jp/jp/auction/d516061039 | I6: https://auctions.yahoo.co.jp/jp/auction/l1236140065 | J6: https://jp.mercari.com/search?keyword=%E3%83%89%E3%83%AB%E3%83%95%E3%82%A3%E3%83%BC%E3%83%89%E3%83%AA%E3%83%BC%E3%83%A0%20%E3%83%A9%E3%83%B3%E3%82%AB&price_min=10000&sort=price&order=asc&status=on_sale | K6: https://jp.mercari.com/search?keyword=%E3%83%89%E3%83%AB%E3%83%95%E3%82%A3%E3%83%BC%E3%83%89%E3%83%AA%E3%83%BC%E3%83%A0%20%E3%83%A9%E3%83%B3%E3%82%AB&price_min=10000&sort=price&order=asc&status=on_sale | L6: https://jp.mercari.com/search?keyword=%E3%83%89%E3%83%AB%E3%83%95%E3%82%A3%E3%83%BC%E3%83%89%E3%83%AA%E3%83%BC%E3%83%A0%20%E3%83%A9%E3%83%B3%E3%82%AB&price_min=10000&sort=price&order=asc&status=on_sale | N6: https://jp.mercari.com/search?keyword=%E3%83%89%E3%83%AB%E3%83%95%E3%82%A3%E3%83%BC%E3%83%89%E3%83%AA%E3%83%BC%E3%83%A0%20%E3%83%A9%E3%83%B3%E3%82%AB&price_min=10000&sort=price&order=asc&status=on_sale | O6: https://fril.jp/s?query=%E3%83%89%E3%83%AB%E3%83%95%E3%82%A3%E3%83%BC%E3%83%89%E3%83%AA%E3%83%BC%E3%83%A0%20%E3%83%A9%E3%83%B3%E3%82%AB&min=10000&transaction=selling | P6: https://search.rakuten.co.jp/search/mall/%E3%83%89%E3%83%AB%E3%83%95%E3%82%A3%E3%83%BC%E3%83%89%E3%83%AA%E3%83%BC%E3%83%A0%20%E3%83%A9%E3%83%B3%E3%82%AB/?min=10000 | Q6: https://auctions.yahoo.co.jp/search/search?p=%E3%83%89%E3%83%AB%E3%83%95%E3%82%A3%E3%83%BC%E3%83%89%E3%83%AA%E3%83%BC%E3%83%A0%20%E3%83%A9%E3%83%B3%E3%82%AB&aucminprice=10000 | R6: https://shopping.yahoo.co.jp/search/%E3%83%89%E3%83%AB%E3%83%95%E3%82%A3%E3%83%BC%E3%83%89%E3%83%AA%E3%83%BC%E3%83%A0%20%E3%83%A9%E3%83%B3%E3%82%AB/0/?pf=10000
A7: 1663 | B7: 吉田遠志 モニュメント・バレー 木版画 | C7: 1 | D7: 91500 | E7: 1250 | F7: Fedex 2.5kg | G7: https://www.ebay.com/sch/i.html?_nkw=Toshi%20Yoshida%20Monument%20Valley%20Woodblock%20Print&_sacat=0&_from=R40&_sop=15&rt=nc&_udlo=20000 | H7: https://page.auctions.yahoo.co.jp/jp/auction/p1231857857 | I7: https://jp.mercari.com/search?keyword=%E5%90%89%E7%94%B0%E9%81%A0%E5%BF%97%20%E3%83%A2%E3%83%8B%E3%83%A5%E3%83%A1%E3%83%B3%E3%83%88%E3%83%BB%E3%83%90%E3%83%AC%E3%83%BC%20%E6%9C%A8%E7%89%88%E7%94%BB&price_min=10000&sort=price&order=asc&status=on_sale | J7: https://jp.mercari.com/search?keyword=%E5%90%89%E7%94%B0%E9%81%A0%E5%BF%97%20%E3%83%A2%E3%83%8B%E3%83%A5%E3%83%A1%E3%83%B3%E3%83%88%E3%83%BB%E3%83%90%E3%83%AC%E3%83%BC%20%E6%9C%A8%E7%89%88%E7%94%BB&price_min=10000&sort=price&order=asc&status=on_sale | K7: https://jp.mercari.com/search?keyword=%E5%90%89%E7%94%B0%E9%81%A0%E5%BF%97%20%E3%83%A2%E3%83%8B%E3%83%A5%E3%83%A1%E3%83%B3%E3%83%88%E3%83%BB%E3%83%90%E3%83%AC%E3%83%BC%20%E6%9C%A8%E7%89%88%E7%94%BB&price_min=10000&sort=price&order=asc&status=on_sale | L7: https://jp.mercari.com/search?keyword=%E5%90%89%E7%94%B0%E9%81%A0%E5%BF%97%20%E3%83%A2%E3%83%8B%E3%83%A5%E3%83%A1%E3%83%B3%E3%83%88%E3%83%BB%E3%83%90%E3%83%AC%E3%83%BC%20%E6%9C%A8%E7%89%88%E7%94%BB&price_min=10000&sort=price&order=asc&status=on_sale | N7: https://jp.mercari.com/search?keyword=%E5%90%89%E7%94%B0%E9%81%A0%E5%BF%97%20%E3%83%A2%E3%83%8B%E3%83%A5%E3%83%A1%E3%83%B3%E3%83%88%E3%83%BB%E3%83%90%E3%83%AC%E3%83%BC%20%E6%9C%A8%E7%89%88%E7%94%BB&price_min=10000&sort=price&order=asc&status=on_sale | O7: https://fril.jp/s?query=%E5%90%89%E7%94%B0%E9%81%A0%E5%BF%97%20%E3%83%A2%E3%83%8B%E3%83%A5%E3%83%A1%E3%83%B3%E3%83%88%E3%83%BB%E3%83%90%E3%83%AC%E3%83%BC%20%E6%9C%A8%E7%89%88%E7%94%BB&min=10000&transaction=selling | P7: https://search.rakuten.co.jp/search/mall/%E5%90%89%E7%94%B0%E9%81%A0%E5%BF%97%20%E3%83%A2%E3%83%8B%E3%83%A5%E3%83%A1%E3%83%B3%E3%83%88%E3%83%BB%E3%83%90%E3%83%AC%E3%83%BC%20%E6%9C%A8%E7%89%88%E7%94%BB/?min=10000 | Q7: https://auctions.yahoo.co.jp/search/search?p=%E5%90%89%E7%94%B0%E9%81%A0%E5%BF%97%20%E3%83%A2%E3%83%8B%E3%83%A5%E3%83%A1%E3%83%B3%E3%83%88%E3%83%BB%E3%83%90%E3%83%AC%E3%83%BC%20%E6%9C%A8%E7%89%88%E7%94%BB&aucminprice=10000 | R7: https://shopping.yahoo.co.jp/search/%E5%90%89%E7%94%B0%E9%81%A0%E5%BF%97%20%E3%83%A2%E3%83%8B%E3%83%A5%E3%83%A1%E3%83%B3%E3%83%88%E3%83%BB%E3%83%90%E3%83%AC%E3%83%BC%20%E6%9C%A8%E7%89%88%E7%94%BB/0/?pf=10000
A8: 1664 | B8: AUTOart マッドマックス インターセプター 2台セット ウェザリング | C8: 1 | D8: 50500 | E8: 592 | F8: Fedex 2.0kg | G8: https://www.ebay.com/sch/i.html?_nkw=AUTOart%20Mad%20Max%20Interceptor&_sacat=0&_from=R40&_sop=15&rt=nc&_udlo=20000 | H8: https://jp.mercari.com/item/m24175944612 | N8: https://jp.mercari.com/search?keyword=AUTOart%20%E3%83%9E%E3%83%83%E3%83%89%E3%83%9E%E3%83%83%E3%82%AF%E3%82%B9%20%E3%82%A4%E3%83%B3%E3%82%BF%E3%83%BC%E3%82%BB%E3%83%97%E3%82%BF%E3%83%BC%202%E5%8F%B0&price_min=10000&sort=price&order=asc&status=on_sale | O8: https://fril.jp/s?query=AUTOart%20%E3%83%9E%E3%83%83%E3%83%89%E3%83%9E%E3%83%83%E3%82%AF%E3%82%B9%20%E3%82%A4%E3%83%B3%E3%82%BF%E3%83%BC%E3%82%BB%E3%83%97%E3%82%BF%E3%83%BC%202%E5%8F%B0&min=10000&transaction=selling | P8: https://search.rakuten.co.jp/search/mall/AUTOart%20%E3%83%9E%E3%83%83%E3%83%89%E3%83%9E%E3%83%83%E3%82%AF%E3%82%B9%20%E3%82%A4%E3%83%B3%E3%82%BF%E3%83%BC%E3%82%BB%E3%83%97%E3%82%BF%E3%83%BC%202%E5%8F%B0/?min=10000 | Q8: https://auctions.yahoo.co.jp/search/search?p=AUTOart%20%E3%83%9E%E3%83%83%E3%83%89%E3%83%9E%E3%83%83%E3%82%AF%E3%82%B9%20%E3%82%A4%E3%83%B3%E3%82%BF%E3%83%BC%E3%82%BB%E3%83%97%E3%82%BF%E3%83%BC%202%E5%8F%B0&aucminprice=10000 | R8: https://shopping.yahoo.co.jp/search/AUTOart%20%E3%83%9E%E3%83%83%E3%83%89%E3%83%9E%E3%83%83%E3%82%AF%E3%82%B9%20%E3%82%A4%E3%83%B3%E3%82%BF%E3%83%BC%E3%82%BB%E3%83%97%E3%82%BF%E3%83%BC%202%E5%8F%B0/0/?pf=10000
A9: 1665 | B9: アオシマ 1/24 マッドマックス2 インターセプター フィギュア | C9: 1 | D9: 31000 | E9: 419 | F9: Fedex 2.0kg | G9: https://www.ebay.com/sch/i.html?_nkw=Aoshima%20Mad%20Max%20Interceptor&_sacat=0&_from=R40&_sop=15&rt=nc&_udlo=20000 | H9: https://jp.mercari.com/item/m64753601502 | N9: https://jp.mercari.com/search?keyword=%E3%83%9E%E3%83%83%E3%83%89%E3%83%9E%E3%83%83%E3%82%AF%E3%82%B9%20%E3%82%A4%E3%83%B3%E3%82%BF%E3%83%BC%E3%82%BB%E3%83%97%E3%82%BF%E3%83%BC%20%E3%83%95%E3%82%A3%E3%82%AE%E3%83%A5%E3%82%A2&price_min=10000&sort=price&order=asc&status=on_sale | O9: https://fril.jp/s?query=%E3%83%9E%E3%83%83%E3%83%89%E3%83%9E%E3%83%83%E3%82%AF%E3%82%B9%20%E3%82%A4%E3%83%B3%E3%82%BF%E3%83%BC%E3%82%BB%E3%83%97%E3%82%BF%E3%83%BC%20%E3%83%95%E3%82%A3%E3%82%AE%E3%83%A5%E3%82%A2&min=10000&transaction=selling | P9: https://search.rakuten.co.jp/search/mall/%E3%83%9E%E3%83%83%E3%83%89%E3%83%9E%E3%83%83%E3%82%AF%E3%82%B9%20%E3%82%A4%E3%83%B3%E3%82%BF%E3%83%BC%E3%82%BB%E3%83%97%E3%82%BF%E3%83%BC%20%E3%83%95%E3%82%A3%E3%82%AE%E3%83%A5%E3%82%A2/?min=10000 | Q9: https://auctions.yahoo.co.jp/search/search?p=%E3%83%9E%E3%83%83%E3%83%89%E3%83%9E%E3%83%83%E3%82%AF%E3%82%B9%20%E3%82%A4%E3%83%B3%E3%82%BF%E3%83%BC%E3%82%BB%E3%83%97%E3%82%BF%E3%83%BC%20%E3%83%95%E3%82%A3%E3%82%AE%E3%83%A5%E3%82%A2&aucminprice=10000 | R9: https://shopping.yahoo.co.jp/search/%E3%83%9E%E3%83%83%E3%83%89%E3%83%9E%E3%83%83%E3%82%AF%E3%82%B9%20%E3%82%A4%E3%83%B3%E3%82%BF%E3%83%BC%E3%82%BB%E3%83%97%E3%82%BF%E3%83%BC%20%E3%83%95%E3%82%A3%E3%82%AE%E3%83%A5%E3%82%A2/0/?pf=10000
A10: 1666 | B10: マッドマックス メルギブソン 1/6 フィギュア プレミアトイズ | C10: 1 | D10: 75000 | E10: 809 | F10: Fedex 2.0kg | G10: https://www.ebay.com/sch/i.html?_nkw=Mad%20Max%20Mel%20Gibson%20Figure&_sacat=0&_from=R40&_sop=15&rt=nc&_udlo=20000 | H10: https://paypayfleamarket.yahoo.co.jp/item/z623953652 | I10: https://jp.mercari.com/item/m35594640581 | N10: https://jp.mercari.com/search?keyword=%E3%83%9E%E3%83%83%E3%83%89%E3%83%9E%E3%83%83%E3%82%AF%E3%82%B9%20%E3%83%95%E3%82%A3%E3%82%AE%E3%83%A5%E3%82%A2%20%E3%83%97%E3%83%AC%E3%83%9F%E3%82%A2%E3%83%88%E3%82%A4%E3%82%BA%201%2F6&price_min=10000&sort=price&order=asc&status=on_sale | O10: https://fril.jp/s?query=%E3%83%9E%E3%83%83%E3%83%89%E3%83%9E%E3%83%83%E3%82%AF%E3%82%B9%20%E3%83%95%E3%82%A3%E3%82%AE%E3%83%A5%E3%82%A2%20%E3%83%97%E3%83%AC%E3%83%9F%E3%82%A2%E3%83%88%E3%82%A4%E3%82%BA%201%2F6&min=10000&transaction=selling | P10: https://search.rakuten.co.jp/search/mall/%E3%83%9E%E3%83%83%E3%83%89%E3%83%9E%E3%83%83%E3%82%AF%E3%82%B9%20%E3%83%95%E3%82%A3%E3%82%AE%E3%83%A5%E3%82%A2%20%E3%83%97%E3%83%AC%E3%83%9F%E3%82%A2%E3%83%88%E3%82%A4%E3%82%BA%201%2F6/?min=10000 | Q10: https://auctions.yahoo.co.jp/search/search?p=%E3%83%9E%E3%83%83%E3%83%89%E3%83%9E%E3%83%83%E3%82%AF%E3%82%B9%20%E3%83%95%E3%82%A3%E3%82%AE%E3%83%A5%E3%82%A2%20%E3%83%97%E3%83%AC%E3%83%9F%E3%82%A2%E3%83%88%E3%82%A4%E3%82%BA%201%2F6&aucminprice=10000 | R10: https://shopping.yahoo.co.jp/search/%E3%83%9E%E3%83%83%E3%83%89%E3%83%9E%E3%83%83%E3%82%AF%E3%82%B9%20%E3%83%95%E3%82%A3%E3%82%AE%E3%83%A5%E3%82%A2%20%E3%83%97%E3%83%AC%E3%83%9F%E3%82%A2%E3%83%88%E3%82%A4%E3%82%BA%201%2F6/0/?pf=10000
A11: 1667 | B11: Bloodborne Tシャツ ガスコイン神父 TORCH TORCH | C11: 1 | D11: 22222 | E11: 294 | F11: Fedex 1.5kg | G11: https://www.ebay.com/sch/i.html?_nkw=Bloodborne%20T-Shirt%20Gascoigne&_sacat=0&_from=R40&_sop=15&rt=nc&_udlo=20000 | H11: https://jp.mercari.com/item/m50698842813 | N11: https://jp.mercari.com/search?keyword=Bloodborne%20T%E3%82%B7%E3%83%A3%E3%83%84%20%E3%82%AC%E3%82%B9%E3%82%B3%E3%82%A4%E3%83%B3%20TORCH%20TORCH&price_min=10000&sort=price&order=asc&status=on_sale | O11: https://fril.jp/s?query=Bloodborne%20T%E3%82%B7%E3%83%A3%E3%83%84%20%E3%82%AC%E3%82%B9%E3%82%B3%E3%82%A4%E3%83%B3%20TORCH%20TORCH&min=10000&transaction=selling | P11: https://search.rakuten.co.jp/search/mall/Bloodborne%20T%E3%82%B7%E3%83%A3%E3%83%84%20%E3%82%AC%E3%82%B9%E3%82%B3%E3%82%A4%E3%83%B3%20TORCH%20TORCH/?min=10000 | Q11: https://auctions.yahoo.co.jp/search/search?p=Bloodborne%20T%E3%82%B7%E3%83%A3%E3%83%84%20%E3%82%AC%E3%82%B9%E3%82%B3%E3%82%A4%E3%83%B3%20TORCH%20TORCH&aucminprice=10000 | R11: https://shopping.yahoo.co.jp/search/Bloodborne%20T%E3%82%B7%E3%83%A3%E3%83%84%20%E3%82%AC%E3%82%B9%E3%82%B3%E3%82%A4%E3%83%B3%20TORCH%20TORCH/0/?pf=10000
